5:return {{["z"] = 0, ["meta"] = {["inventory"] = {}, ["fields"] = {}}, ["param1"] = 87, ["name"] = "wool:grey", ["x"] = 0, ["y"] = 0}, {["z"] = 1, ["meta"] = {["inventory"] = {}, ["fields"] = {}}, ["param1"] = 87, ["name"] = "wool:grey", ["x"] = 0, ["y"] = 0}, {["z"] = 14, ["meta"] = {["inventory"] = {}, ["fields"] = {}}, ["param1"] = 87, ["name"] = "wool:grey", ["x"] = 0, ["y"] = 0}, {["z"] = 15, ["meta"] = {["inventory"] = {}, ["fields"] = {}}, ["param1"] = 87, ["name"] = "wool:grey", ["x"] = 0, ["y"] = 0}, {["z"] = 0, ["meta"] = {["inventory"] = {}, ["fields"] = {}}, ["param1"] = 87, ["name"] = "wool:grey", ["x"] = 0, ["y"] = 1}, {["z"] = 1, ["meta"] = {["inventory"] = {}, ["fields"] = {}}, ["param1"] = 87, ["name"] = "wool:grey", ["x"] = 0, ["y"] = 1}, {["z"] = 14, ["meta"] = {["inventory"] = {}, ["fields"] = {}}, ["param1"] = 87, ["name"] = "wool:grey", ["x"] = 0, ["y"] = 1}, {["z"] = 15, ["meta"] = {["inventory"] = {}, ["fields"] = {}}, ["param1"] = 87, ["name"] = "wool:grey", ["x"] = 0, ["y"] = 1}, {["z"] = 0, ["meta"] = {["inventory"] = {}, ["fields"] = {}}, ["param1"] = 87, ["name"] = "wool:grey", ["x"] = 0, ["y"] = 2}, {["z"] = 1, ["meta"] = {["inventory"] = {}, ["fields"] = {}}, ["param1"] = 87, ["name"] = "wool:grey", ["x"] = 0, ["y"] = 2}, {["z"] = 14, ["meta"] = {["inventory"] = {}, ["fields"] = {}}, ["param1"] = 87, ["name"] = "wool:grey", ["x"] = 0, ["y"] = 2}, {["z"] = 15, ["meta"] = {["inventory"] = {}, ["fields"] = {}}, ["param1"] = 87, ["name"] = "wool:grey", ["x"] = 0, ["y"] = 2}, {["z"] = 0, ["meta"] = {["inventory"] = {}, ["fields"] = {}}, ["param1"] = 87, ["name"] = "wool:grey", ["x"] = 0, ["y"] = 3}, {["z"] = 1, ["meta"] = {["inventory"] = {}, ["fields"] = {}}, ["param1"] = 87, ["name"] = "wool:grey", ["x"] = 0, ["y"] = 3}, {["z"] = 14, ["meta"] = {["inventory"] = {}, ["fields"] = {}}, ["param1"] = 87, ["name"] = "wool:grey", ["x"] = 0, ["y"] = 3}, {["z"] = 15, ["meta"] = {["inventory"] = {}, ["fields"] = {}}, ["param1"] = 87, ["name"] = "wool:grey", ["x"] = 0, ["y"] = 3}, {["z"] = 0, ["meta"] = {["inventory"] = {}, ["fields"] = {}}, ["param1"] = 87, ["name"] = "wool:grey", ["x"] = 0, ["y"] = 4}, {["z"] = 1, ["meta"] = {["inventory"] = {}, ["fields"] = {}}, ["param1"] = 87, ["name"] = "wool:grey", ["x"] = 0, ["y"] = 4}, {["z"] = 14, ["meta"] = {["inventory"] = {}, ["fields"] = {}}, ["param1"] = 87, ["name"] = "wool:grey", ["x"] = 0, ["y"] = 4}, {["z"] = 15, ["meta"] = {["inventory"] = {}, ["fields"] = {}}, ["param1"] = 87, ["name"] = "wool:grey", ["x"] = 0, ["y"] = 4}, {["z"] = 0, ["meta"] = {["inventory"] = {}, ["fields"] = {}}, ["param1"] = 87, ["name"] = "wool:grey", ["x"] = 0, ["y"] = 5}, {["z"] = 1, ["meta"] = {["inventory"] = {}, ["fields"] = {}}, ["param1"] = 87, ["name"] = "wool:grey", ["x"] = 0, ["y"] = 5}, {["z"] = 14, ["meta"] = {["inventory"] = {}, ["fields"] = {}}, ["param1"] = 87, ["name"] = "wool:grey", ["x"] = 0, ["y"] = 5}, {["z"] = 15, ["meta"] = {["inventory"] = {}, ["fields"] = {}}, ["param1"] = 87, ["name"] = "wool:grey", ["x"] = 0, ["y"] = 5}, {["z"] = 0, ["meta"] = {["inventory"] = {}, ["fields"] = {}}, ["param1"] = 87, ["name"] = "wool:grey", ["x"] = 0, ["y"] = 6}, {["z"] = 1, ["meta"] = {["inventory"] = {}, ["fields"] = {}}, ["param1"] = 87, ["name"] = "wool:grey", ["x"] = 0, ["y"] = 6}, {["z"] = 14, ["meta"] = {["inventory"] = {}, ["fields"] = {}}, ["param1"] = 87, ["name"] = "wool:grey", ["x"] = 0, ["y"] = 6}, {["z"] = 15, ["meta"] = {["inventory"] = {}, ["fields"] = {}}, ["param1"] = 87, ["name"] = "wool:grey", ["x"] = 0, ["y"] = 6}, {["z"] = 0, ["meta"] = {["inventory"] = {}, ["fields"] = {}}, ["param1"] = 87, ["name"] = "wool:grey", ["x"] = 0, ["y"] = 7}, {["z"] = 1, ["meta"] = {["inventory"] = {}, ["fields"] = {}}, ["param1"] = 87, ["name"] = "wool:grey", ["x"] = 0, ["y"] = 7}, {["z"] = 14, ["meta"] = {["inventory"] = {}, ["fields"] = {}}, ["param1"] = 87, ["name"] = "wool:grey", ["x"] = 0, ["y"] = 7}, {["z"] = 15, ["meta"] = {["inventory"] = {}, ["fields"] = {}}, ["param1"] = 87, ["name"] = "wool:grey", ["x"] = 0, ["y"] = 7}, {["z"] = 0, ["meta"] = {["inventory"] = {}, ["fields"] = {}}, ["param1"] = 87, ["name"] = "wool:grey", ["x"] = 0, ["y"] = 8}, {["z"] = 1, ["meta"] = {["inventory"] = {}, ["fields"] = {}}, ["param1"] = 87, ["name"] = "wool:grey", ["x"] = 0, ["y"] = 8}, {["z"] = 14, ["meta"] = {["inventory"] = {}, ["fields"] = {}}, ["param1"] = 87, ["name"] = "wool:grey", ["x"] = 0, ["y"] = 8}, {["z"] = 15, ["meta"] = {["inventory"] = {}, ["fields"] = {}}, ["param1"] = 87, ["name"] = "wool:grey", ["x"] = 0, ["y"] = 8}, {["z"] = 0, ["meta"] = {["inventory"] = {}, ["fields"] = {}}, ["param1"] = 87, ["name"] = "wool:grey", ["x"] = 0, ["y"] = 9}, {["z"] = 1, ["meta"] = {["inventory"] = {}, ["fields"] = {}}, ["param1"] = 87, ["name"] = "wool:grey", ["x"] = 0, ["y"] = 9}, {["z"] = 14, ["meta"] = {["inventory"] = {}, ["fields"] = {}}, ["param1"] = 87, ["name"] = "wool:grey", ["x"] = 0, ["y"] = 9}, {["z"] = 15, ["meta"] = {["inventory"] = {}, ["fields"] = {}}, ["param1"] = 87, ["name"] = "wool:grey", ["x"] = 0, ["y"] = 9}, {["z"] = 0, ["meta"] = {["inventory"] = {}, ["fields"] = {}}, ["param1"] = 87, ["name"] = "wool:grey", ["x"] = 0, ["y"] = 10}, {["z"] = 1, ["meta"] = {["inventory"] = {}, ["fields"] = {}}, ["param1"] = 87, ["name"] = "wool:grey", ["x"] = 0, ["y"] = 10}, {["z"] = 14, ["meta"] = {["inventory"] = {}, ["fields"] = {}}, ["param1"] = 87, ["name"] = "wool:grey", ["x"] = 0, ["y"] = 10}, {["z"] = 15, ["meta"] = {["inventory"] = {}, ["fields"] = {}}, ["param1"] = 87, ["name"] = "wool:grey", ["x"] = 0, ["y"] = 10}, {["z"] = 0, ["meta"] = {["inventory"] = {}, ["fields"] = {}}, ["param1"] = 87, ["name"] = "wool:grey", ["x"] = 0, ["y"] = 11}, {["z"] = 1, ["meta"] = {["inventory"] = {}, ["fields"] = {}}, ["param1"] = 87, ["name"] = "wool:grey", ["x"] = 0, ["y"] = 11}, {["z"] = 14, ["meta"] = {["inventory"] = {}, ["fields"] = {}}, ["param1"] = 87, ["name"] = "wool:grey", ["x"] = 0, ["y"] = 11}, {["z"] = 15, ["meta"] = {["inventory"] = {}, ["fields"] = {}}, ["param1"] = 87, ["name"] = "wool:grey", ["x"] = 0, ["y"] = 11}, {["z"] = 0, ["meta"] = {["inventory"] = {}, ["fields"] = {}}, ["param1"] = 87, ["name"] = "wool:grey", ["x"] = 0, ["y"] = 12}, {["z"] = 1, ["meta"] = {["inventory"] = {}, ["fields"] = {}}, ["param1"] = 87, ["name"] = "wool:grey", ["x"] = 0, ["y"] = 12}, {["z"] = 14, ["meta"] = {["inventory"] = {}, ["fields"] = {}}, ["param1"] = 87, ["name"] = "wool:grey", ["x"] = 0, ["y"] = 12}, {["z"] = 15, ["meta"] = {["inventory"] = {}, ["fields"] = {}}, ["param1"] = 87, ["name"] = "wool:grey", ["x"] = 0, ["y"] = 12}, {["z"] = 0, ["meta"] = {["inventory"] = {}, ["fields"] = {}}, ["param1"] = 87, ["name"] = "wool:grey", ["x"] = 0, ["y"] = 13}, {["z"] = 1, ["meta"] = {["inventory"] = {}, ["fields"] = {}}, ["param1"] = 87, ["name"] = "wool:grey", ["x"] = 0, ["y"] = 13}, {["z"] = 14, ["meta"] = {["inventory"] = {}, ["fields"] = {}}, ["param1"] = 87, ["name"] = "wool:grey", ["x"] = 0, ["y"] = 13}, {["z"] = 15, ["meta"] = {["inventory"] = {}, ["fields"] = {}}, ["param1"] = 87, ["name"] = "wool:grey", ["x"] = 0, ["y"] = 13}, {["z"] = 0, ["meta"] = {["inventory"] = {}, ["fields"] = {}}, ["param1"] = 87, ["name"] = "wool:grey", ["x"] = 0, ["y"] = 14}, {["z"] = 1, ["meta"] = {["inventory"] = {}, ["fields"] = {}}, ["param1"] = 87, ["name"] = "wool:grey", ["x"] = 0, ["y"] = 14}, {["z"] = 14, ["meta"] = {["inventory"] = {}, ["fields"] = {}}, ["param1"] = 87, ["name"] = "wool:grey", ["x"] = 0, ["y"] = 14}, {["z"] = 15, ["meta"] = {["inventory"] = {}, ["fields"] = {}}, ["param1"] = 87, ["name"] = "wool:grey", ["x"] = 0, ["y"] = 14}, {["z"] = 0, ["meta"] = {["inventory"] = {}, ["fields"] = {}}, ["param1"] = 87, ["name"] = "wool:grey", ["x"] = 0, ["y"] = 15}, {["z"] = 1, ["meta"] = {["inventory"] = {}, ["fields"] = {}}, ["param1"] = 87, ["name"] = "wool:grey", ["x"] = 0, ["y"] = 15}, {["z"] = 14, ["meta"] = {["inventory"] = {}, ["fields"] = {}}, ["param1"] = 87, ["name"] = "wool:grey", ["x"] = 0, ["y"] = 15}, {["z"] = 15, ["meta"] = {["inventory"] = {}, ["fields"] = {}}, ["param1"] = 87, ["name"] = "wool:grey", ["x"] = 0, ["y"] = 15}, {["z"] = 0, ["meta"] = {["inventory"] = {}, ["fields"] = {}}, ["param1"] = 87, ["name"] = "wool:grey", ["x"] = 0, ["y"] = 16}, {["z"] = 1, ["meta"] = {["inventory"] = {}, ["fields"] = {}}, ["param1"] = 87, ["name"] = "wool:grey", ["x"] = 0, ["y"] = 16}, {["z"] = 14, ["meta"] = {["inventory"] = {}, ["fields"] = {}}, ["param1"] = 87, ["name"] = "wool:grey", ["x"] = 0, ["y"] = 16}, {["z"] = 15, ["meta"] = {["inventory"] = {}, ["fields"] = {}}, ["param1"] = 87, ["name"] = "wool:grey", ["x"] = 0, ["y"] = 16}, {["z"] = 0, ["meta"] = {["inventory"] = {}, ["fields"] = {}}, ["param1"] = 87, ["name"] = "wool:grey", ["x"] = 0, ["y"] = 17}, {["z"] = 1, ["meta"] = {["inventory"] = {}, ["fields"] = {}}, ["param1"] = 87, ["name"] = "wool:grey", ["x"] = 0, ["y"] = 17}, {["z"] = 14, ["meta"] = {["inventory"] = {}, ["fields"] = {}}, ["param1"] = 87, ["name"] = "wool:grey", ["x"] = 0, ["y"] = 17}, {["z"] = 15, ["meta"] = {["inventory"] = {}, ["fields"] = {}}, ["param1"] = 87, ["name"] = "wool:grey", ["x"] = 0, ["y"] = 17}, {["z"] = 0, ["meta"] = {["inventory"] = {}, ["fields"] = {}}, ["param1"] = 87, ["name"] = "wool:grey", ["x"] = 0, ["y"] = 18}, {["z"] = 1, ["meta"] = {["inventory"] = {}, ["fields"] = {}}, ["param1"] = 87, ["name"] = "wool:grey", ["x"] = 0, ["y"] = 18}, {["z"] = 14, ["meta"] = {["inventory"] = {}, ["fields"] = {}}, ["param1"] = 87, ["name"] = "wool:grey", ["x"] = 0, ["y"] = 18}, {["z"] = 15, ["meta"] = {["inventory"] = {}, ["fields"] = {}}, ["param1"] = 87, ["name"] = "wool:grey", ["x"] = 0, ["y"] = 18}, {["z"] = 0, ["meta"] = {["inventory"] = {}, ["fields"] = {}}, ["param1"] = 87, ["name"] = "wool:grey", ["x"] = 0, ["y"] = 19}, {["z"] = 1, ["meta"] = {["inventory"] = {}, ["fields"] = {}}, ["param1"] = 87, ["name"] = "wool:grey", ["x"] = 0, ["y"] = 19}, {["z"] = 14, ["meta"] = {["inventory"] = {}, ["fields"] = {}}, ["param1"] = 87, ["name"] = "wool:grey", ["x"] = 0, ["y"] = 19}, {["z"] = 15, ["meta"] = {["inventory"] = {}, ["fields"] = {}}, ["param1"] = 87, ["name"] = "wool:grey", ["x"] = 0, ["y"] = 19}, {["z"] = 0, ["meta"] = {["inventory"] = {}, ["fields"] = {}}, ["param1"] = 87, ["name"] = "wool:grey", ["x"] = 0, ["y"] = 20}, {["z"] = 1, ["meta"] = {["inventory"] = {}, ["fields"] = {}}, ["param1"] = 87, ["name"] = "wool:grey", ["x"] = 0, ["y"] = 20}, {["z"] = 14, ["meta"] = {["inventory"] = {}, ["fields"] = {}}, ["param1"] = 87, ["name"] = "wool:grey", ["x"] = 0, ["y"] = 20}, {["z"] = 15, ["meta"] = {["inventory"] = {}, ["fields"] = {}}, ["param1"] = 87, ["name"] = "wool:grey", ["x"] = 0, ["y"] = 20}, {["z"] = 0, ["meta"] = {["inventory"] = {}, ["fields"] = {}}, ["param1"] = 87, ["name"] = "wool:grey", ["x"] = 0, ["y"] = 21}, {["z"] = 1, ["meta"] = {["inventory"] = {}, ["fields"] = {}}, ["param1"] = 87, ["name"] = "wool:grey", ["x"] = 0, ["y"] = 21}, {["z"] = 14, ["meta"] = {["inventory"] = {}, ["fields"] = {}}, ["param1"] = 87, ["name"] = "wool:grey", ["x"] = 0, ["y"] = 21}, {["z"] = 15, ["meta"] = {["inventory"] = {}, ["fields"] = {}}, ["param1"] = 87, ["name"] = "wool:grey", ["x"] = 0, ["y"] = 21}, {["z"] = 0, ["meta"] = {["inventory"] = {}, ["fields"] = {}}, ["param1"] = 87, ["name"] = "wool:grey", ["x"] = 0, ["y"] = 22}, {["z"] = 1, ["meta"] = {["inventory"] = {}, ["fields"] = {}}, ["param1"] = 87, ["name"] = "wool:grey", ["x"] = 0, ["y"] = 22}, {["z"] = 14, ["meta"] = {["inventory"] = {}, ["fields"] = {}}, ["param1"] = 87, ["name"] = "wool:grey", ["x"] = 0, ["y"] = 22}, {["z"] = 15, ["meta"] = {["inventory"] = {}, ["fields"] = {}}, ["param1"] = 87, ["name"] = "wool:grey", ["x"] = 0, ["y"] = 22}, {["z"] = 0, ["meta"] = {["inventory"] = {}, ["fields"] = {}}, ["param1"] = 87, ["name"] = "wool:grey", ["x"] = 0, ["y"] = 23}, {["z"] = 1, ["meta"] = {["inventory"] = {}, ["fields"] = {}}, ["param1"] = 87, ["name"] = "wool:grey", ["x"] = 0, ["y"] = 23}, {["z"] = 14, ["meta"] = {["inventory"] = {}, ["fields"] = {}}, ["param1"] = 87, ["name"] = "wool:grey", ["x"] = 0, ["y"] = 23}, {["z"] = 15, ["meta"] = {["inventory"] = {}, ["fields"] = {}}, ["param1"] = 87, ["name"] = "wool:grey", ["x"] = 0, ["y"] = 23}, {["z"] = 0, ["meta"] = {["inventory"] = {}, ["fields"] = {}}, ["param1"] = 87, ["name"] = "wool:grey", ["x"] = 0, ["y"] = 24}, {["z"] = 1, ["meta"] = {["inventory"] = {}, ["fields"] = {}}, ["param1"] = 87, ["name"] = "wool:grey", ["x"] = 0, ["y"] = 24}, {["z"] = 14, ["meta"] = {["inventory"] = {}, ["fields"] = {}}, ["param1"] = 87, ["name"] = "wool:grey", ["x"] = 0, ["y"] = 24}, {["z"] = 15, ["meta"] = {["inventory"] = {}, ["fields"] = {}}, ["param1"] = 87, ["name"] = "wool:grey", ["x"] = 0, ["y"] = 24}, {["z"] = 0, ["meta"] = {["inventory"] = {}, ["fields"] = {}}, ["param1"] = 87, ["name"] = "wool:grey", ["x"] = 0, ["y"] = 25}, {["z"] = 1, ["meta"] = {["inventory"] = {}, ["fields"] = {}}, ["param1"] = 87, ["name"] = "wool:grey", ["x"] = 0, ["y"] = 25}, {["z"] = 14, ["meta"] = {["inventory"] = {}, ["fields"] = {}}, ["param1"] = 87, ["name"] = "wool:grey", ["x"] = 0, ["y"] = 25}, {["z"] = 15, ["meta"] = {["inventory"] = {}, ["fields"] = {}}, ["param1"] = 87, ["name"] = "wool:grey", ["x"] = 0, ["y"] = 25}, {["z"] = 0, ["meta"] = {["inventory"] = {}, ["fields"] = {}}, ["param1"] = 87, ["name"] = "wool:grey", ["x"] = 0, ["y"] = 26}, {["z"] = 1, ["meta"] = {["inventory"] = {}, ["fields"] = {}}, ["param1"] = 87, ["name"] = "wool:grey", ["x"] = 0, ["y"] = 26}, {["z"] = 14, ["meta"] = {["inventory"] = {}, ["fields"] = {}}, ["param1"] = 87, ["name"] = "wool:grey", ["x"] = 0, ["y"] = 26}, {["z"] = 15, ["meta"] = {["inventory"] = {}, ["fields"] = {}}, ["param1"] = 87, ["name"] = "wool:grey", ["x"] = 0, ["y"] = 26}, {["z"] = 0, ["meta"] = {["inventory"] = {}, ["fields"] = {}}, ["param1"] = 87, ["name"] = "wool:grey", ["x"] = 0, ["y"] = 27}, {["z"] = 1, ["meta"] = {["inventory"] = {}, ["fields"] = {}}, ["param1"] = 87, ["name"] = "wool:grey", ["x"] = 0, ["y"] = 27}, {["z"] = 14, ["meta"] = {["inventory"] = {}, ["fields"] = {}}, ["param1"] = 87, ["name"] = "wool:grey", ["x"] = 0, ["y"] = 27}, {["z"] = 15, ["meta"] = {["inventory"] = {}, ["fields"] = {}}, ["param1"] = 87, ["name"] = "wool:grey", ["x"] = 0, ["y"] = 27}, {["z"] = 0, ["meta"] = {["inventory"] = {}, ["fields"] = {}}, ["param1"] = 87, ["name"] = "wool:grey", ["x"] = 0, ["y"] = 28}, {["z"] = 1, ["meta"] = {["inventory"] = {}, ["fields"] = {}}, ["param1"] = 87, ["name"] = "wool:grey", ["x"] = 0, ["y"] = 28}, {["z"] = 14, ["meta"] = {["inventory"] = {}, ["fields"] = {}}, ["param1"] = 87, ["name"] = "wool:grey", ["x"] = 0, ["y"] = 28}, {["z"] = 15, ["meta"] = {["inventory"] = {}, ["fields"] = {}}, ["param1"] = 87, ["name"] = "wool:grey", ["x"] = 0, ["y"] = 28}, {["z"] = 0, ["meta"] = {["inventory"] = {}, ["fields"] = {}}, ["param1"] = 87, ["name"] = "wool:grey", ["x"] = 0, ["y"] = 29}, {["z"] = 1, ["meta"] = {["inventory"] = {}, ["fields"] = {}}, ["param1"] = 87, ["name"] = "wool:grey", ["x"] = 0, ["y"] = 29}, {["z"] = 14, ["meta"] = {["inventory"] = {}, ["fields"] = {}}, ["param1"] = 87, ["name"] = "wool:grey", ["x"] = 0, ["y"] = 29}, {["z"] = 15, ["meta"] = {["inventory"] = {}, ["fields"] = {}}, ["param1"] = 87, ["name"] = "wool:grey", ["x"] = 0, ["y"] = 29}, {["z"] = 0, ["meta"] = {["inventory"] = {}, ["fields"] = {}}, ["param1"] = 87, ["name"] = "wool:grey", ["x"] = 0, ["y"] = 30}, {["z"] = 1, ["meta"] = {["inventory"] = {}, ["fields"] = {}}, ["param1"] = 87, ["name"] = "wool:grey", ["x"] = 0, ["y"] = 30}, {["z"] = 14, ["meta"] = {["inventory"] = {}, ["fields"] = {}}, ["param1"] = 87, ["name"] = "wool:grey", ["x"] = 0, ["y"] = 30}, {["z"] = 15, ["meta"] = {["inventory"] = {}, ["fields"] = {}}, ["param1"] = 87, ["name"] = "wool:grey", ["x"] = 0, ["y"] = 30}, {["z"] = 0, ["meta"] = {["inventory"] = {}, ["fields"] = {}}, ["param1"] = 87, ["name"] = "wool:grey", ["x"] = 0, ["y"] = 31}, {["z"] = 1, ["meta"] = {["inventory"] = {}, ["fields"] = {}}, ["param1"] = 87, ["name"] = "wool:grey", ["x"] = 0, ["y"] = 31}, {["z"] = 14, ["meta"] = {["inventory"] = {}, ["fields"] = {}}, ["param1"] = 87, ["name"] = "wool:grey", ["x"] = 0, ["y"] = 31}, {["z"] = 15, ["meta"] = {["inventory"] = {}, ["fields"] = {}}, ["param1"] = 87, ["name"] = "wool:grey", ["x"] = 0, ["y"] = 31}, {["z"] = 0, ["meta"] = {["inventory"] = {}, ["fields"] = {}}, ["param1"] = 87, ["name"] = "wool:grey", ["x"] = 1, ["y"] = 0}, {["z"] = 1, ["meta"] = {["inventory"] = {}, ["fields"] = {}}, ["param1"] = 87, ["name"] = "wool:grey", ["x"] = 1, ["y"] = 0}, {["z"] = 14, ["meta"] = {["inventory"] = {}, ["fields"] = {}}, ["param1"] = 87, ["name"] = "wool:grey", ["x"] = 1, ["y"] = 0}, {["z"] = 15, ["meta"] = {["inventory"] = {}, ["fields"] = {}}, ["param1"] = 87, ["name"] = "wool:grey", ["x"] = 1, ["y"] = 0}, {["z"] = 0, ["meta"] = {["inventory"] = {}, ["fields"] = {}}, ["param1"] = 87, ["name"] = "wool:grey", ["x"] = 1, ["y"] = 1}, {["z"] = 1, ["meta"] = {["inventory"] = {}, ["fields"] = {}}, ["param1"] = 87, ["name"] = "wool:grey", ["x"] = 1, ["y"] = 1}, {["z"] = 14, ["meta"] = {["inventory"] = {}, ["fields"] = {}}, ["param1"] = 87, ["name"] = "wool:grey", ["x"] = 1, ["y"] = 1}, {["z"] = 15, ["meta"] = {["inventory"] = {}, ["fields"] = {}}, ["param1"] = 87, ["name"] = "wool:grey", ["x"] = 1, ["y"] = 1}, {["z"] = 0, ["meta"] = {["inventory"] = {}, ["fields"] = {}}, ["param1"] = 87, ["name"] = "wool:grey", ["x"] = 1, ["y"] = 2}, {["z"] = 1, ["meta"] = {["inventory"] = {}, ["fields"] = {}}, ["param1"] = 87, ["name"] = "wool:grey", ["x"] = 1, ["y"] = 2}, {["z"] = 14, ["meta"] = {["inventory"] = {}, ["fields"] = {}}, ["param1"] = 87, ["name"] = "wool:grey", ["x"] = 1, ["y"] = 2}, {["z"] = 15, ["meta"] = {["inventory"] = {}, ["fields"] = {}}, ["param1"] = 87, ["name"] = "wool:grey", ["x"] = 1, ["y"] = 2}, {["z"] = 0, ["meta"] = {["inventory"] = {}, ["fields"] = {}}, ["param1"] = 87, ["name"] = "wool:grey", ["x"] = 1, ["y"] = 3}, {["z"] = 1, ["meta"] = {["inventory"] = {}, ["fields"] = {}}, ["param1"] = 87, ["name"] = "wool:grey", ["x"] = 1, ["y"] = 3}, {["z"] = 14, ["meta"] = {["inventory"] = {}, ["fields"] = {}}, ["param1"] = 87, ["name"] = "wool:grey", ["x"] = 1, ["y"] = 3}, {["z"] = 15, ["meta"] = {["inventory"] = {}, ["fields"] = {}}, ["param1"] = 87, ["name"] = "wool:grey", ["x"] = 1, ["y"] = 3}, {["z"] = 0, ["meta"] = {["inventory"] = {}, ["fields"] = {}}, ["param1"] = 87, ["name"] = "wool:grey", ["x"] = 1, ["y"] = 4}, {["z"] = 1, ["meta"] = {["inventory"] = {}, ["fields"] = {}}, ["param1"] = 87, ["name"] = "wool:grey", ["x"] = 1, ["y"] = 4}, {["z"] = 14, ["meta"] = {["inventory"] = {}, ["fields"] = {}}, ["param1"] = 87, ["name"] = "wool:grey", ["x"] = 1, ["y"] = 4}, {["z"] = 15, ["meta"] = {["inventory"] = {}, ["fields"] = {}}, ["param1"] = 87, ["name"] = "wool:grey", ["x"] = 1, ["y"] = 4}, {["z"] = 0, ["meta"] = {["inventory"] = {}, ["fields"] = {}}, ["param1"] = 87, ["name"] = "wool:grey", ["x"] = 1, ["y"] = 5}, {["z"] = 1, ["meta"] = {["inventory"] = {}, ["fields"] = {}}, ["param1"] = 87, ["name"] = "wool:grey", ["x"] = 1, ["y"] = 5}, {["z"] = 14, ["meta"] = {["inventory"] = {}, ["fields"] = {}}, ["param1"] = 87, ["name"] = "wool:grey", ["x"] = 1, ["y"] = 5}, {["z"] = 15, ["meta"] = {["inventory"] = {}, ["fields"] = {}}, ["param1"] = 87, ["name"] = "wool:grey", ["x"] = 1, ["y"] = 5}, {["z"] = 0, ["meta"] = {["inventory"] = {}, ["fields"] = {}}, ["param1"] = 87, ["name"] = "wool:grey", ["x"] = 1, ["y"] = 6}, {["z"] = 1, ["meta"] = {["inventory"] = {}, ["fields"] = {}}, ["param1"] = 87, ["name"] = "wool:grey", ["x"] = 1, ["y"] = 6}, {["z"] = 2, ["meta"] = {["inventory"] = {}, ["fields"] = {}}, ["param1"] = 87, ["name"] = "wool:grey", ["x"] = 1, ["y"] = 6}, {["z"] = 3, ["meta"] = {["inventory"] = {}, ["fields"] = {}}, ["param1"] = 87, ["name"] = "wool:grey", ["x"] = 1, ["y"] = 6}, {["z"] = 4, ["meta"] = {["inventory"] = {}, ["fields"] = {}}, ["param1"] = 87, ["name"] = "wool:grey", ["x"] = 1, ["y"] = 6}, {["z"] = 5, ["meta"] = {["inventory"] = {}, ["fields"] = {}}, ["param1"] = 87, ["name"] = "wool:grey", ["x"] = 1, ["y"] = 6}, {["z"] = 6, ["meta"] = {["inventory"] = {}, ["fields"] = {}}, ["param1"] = 87, ["name"] = "wool:grey", ["x"] = 1, ["y"] = 6}, {["z"] = 7, ["meta"] = {["inventory"] = {}, ["fields"] = {}}, ["param1"] = 87, ["name"] = "wool:grey", ["x"] = 1, ["y"] = 6}, {["z"] = 8, ["meta"] = {["inventory"] = {}, ["fields"] = {}}, ["param1"] = 87, ["name"] = "wool:grey", ["x"] = 1, ["y"] = 6}, {["z"] = 9, ["meta"] = {["inventory"] = {}, ["fields"] = {}}, ["param1"] = 87, ["name"] = "wool:grey", ["x"] = 1, ["y"] = 6}, {["z"] = 10, ["meta"] = {["inventory"] = {}, ["fields"] = {}}, ["param1"] = 87, ["name"] = "wool:grey", ["x"] = 1, ["y"] = 6}, {["z"] = 11, ["meta"] = {["inventory"] = {}, ["fields"] = {}}, ["param1"] = 87, ["name"] = "wool:grey", ["x"] = 1, ["y"] = 6}, {["z"] = 12, ["meta"] = {["inventory"] = {}, ["fields"] = {}}, ["param1"] = 87, ["name"] = "wool:grey", ["x"] = 1, ["y"] = 6}, {["z"] = 13, ["meta"] = {["inventory"] = {}, ["fields"] = {}}, ["param1"] = 87, ["name"] = "wool:grey", ["x"] = 1, ["y"] = 6}, {["z"] = 14, ["meta"] = {["inventory"] = {}, ["fields"] = {}}, ["param1"] = 87, ["name"] = "wool:grey", ["x"] = 1, ["y"] = 6}, {["z"] = 15, ["meta"] = {["inventory"] = {}, ["fields"] = {}}, ["param1"] = 87, ["name"] = "wool:grey", ["x"] = 1, ["y"] = 6}, {["z"] = 0, ["meta"] = {["inventory"] = {}, ["fields"] = {}}, ["param1"] = 87, ["name"] = "wool:grey", ["x"] = 1, ["y"] = 7}, {["z"] = 1, ["meta"] = {["inventory"] = {}, ["fields"] = {}}, ["param1"] = 87, ["name"] = "wool:grey", ["x"] = 1, ["y"] = 7}, {["z"] = 6, ["meta"] = {["inventory"] = {}, ["fields"] = {}}, ["param1"] = 87, ["name"] = "wool:grey", ["x"] = 1, ["y"] = 7}, {["z"] = 9, ["meta"] = {["inventory"] = {}, ["fields"] = {}}, ["param1"] = 87, ["name"] = "wool:grey", ["x"] = 1, ["y"] = 7}, {["z"] = 14, ["meta"] = {["inventory"] = {}, ["fields"] = {}}, ["param1"] = 87, ["name"] = "wool:grey", ["x"] = 1, ["y"] = 7}, {["z"] = 15, ["meta"] = {["inventory"] = {}, ["fields"] = {}}, ["param1"] = 87, ["name"] = "wool:grey", ["x"] = 1, ["y"] = 7}, {["z"] = 0, ["meta"] = {["inventory"] = {}, ["fields"] = {}}, ["param1"] = 87, ["name"] = "wool:grey", ["x"] = 1, ["y"] = 8}, {["z"] = 1, ["meta"] = {["inventory"] = {}, ["fields"] = {}}, ["param1"] = 87, ["name"] = "wool:grey", ["x"] = 1, ["y"] = 8}, {["z"] = 6, ["meta"] = {["inventory"] = {}, ["fields"] = {}}, ["param1"] = 87, ["name"] = "wool:grey", ["x"] = 1, ["y"] = 8}, {["z"] = 9, ["meta"] = {["inventory"] = {}, ["fields"] = {}}, ["param1"] = 87, ["name"] = "wool:grey", ["x"] = 1, ["y"] = 8}, {["z"] = 14, ["meta"] = {["inventory"] = {}, ["fields"] = {}}, ["param1"] = 87, ["name"] = "wool:grey", ["x"] = 1, ["y"] = 8}, {["z"] = 15, ["meta"] = {["inventory"] = {}, ["fields"] = {}}, ["param1"] = 87, ["name"] = "wool:grey", ["x"] = 1, ["y"] = 8}, {["z"] = 0, ["meta"] = {["inventory"] = {}, ["fields"] = {}}, ["param1"] = 87, ["name"] = "wool:grey", ["x"] = 1, ["y"] = 9}, {["z"] = 1, ["meta"] = {["inventory"] = {}, ["fields"] = {}}, ["param1"] = 87, ["name"] = "wool:grey", ["x"] = 1, ["y"] = 9}, {["z"] = 2, ["meta"] = {["inventory"] = {}, ["fields"] = {}}, ["param1"] = 87, ["name"] = "wool:grey", ["x"] = 1, ["y"] = 9}, {["z"] = 3, ["meta"] = {["inventory"] = {}, ["fields"] = {}}, ["param1"] = 87, ["name"] = "wool:grey", ["x"] = 1, ["y"] = 9}, {["z"] = 4, ["meta"] = {["inventory"] = {}, ["fields"] = {}}, ["param1"] = 87, ["name"] = "wool:grey", ["x"] = 1, ["y"] = 9}, {["z"] = 5, ["meta"] = {["inventory"] = {}, ["fields"] = {}}, ["param1"] = 87, ["name"] = "wool:grey", ["x"] = 1, ["y"] = 9}, {["z"] = 6, ["meta"] = {["inventory"] = {}, ["fields"] = {}}, ["param1"] = 87, ["name"] = "wool:grey", ["x"] = 1, ["y"] = 9}, {["z"] = 7, ["meta"] = {["inventory"] = {}, ["fields"] = {}}, ["param1"] = 87, ["name"] = "wool:grey", ["x"] = 1, ["y"] = 9}, {["z"] = 8, ["meta"] = {["inventory"] = {}, ["fields"] = {}}, ["param1"] = 87, ["name"] = "wool:grey", ["x"] = 1, ["y"] = 9}, {["z"] = 9, ["meta"] = {["inventory"] = {}, ["fields"] = {}}, ["param1"] = 87, ["name"] = "wool:grey", ["x"] = 1, ["y"] = 9}, {["z"] = 10, ["meta"] = {["inventory"] = {}, ["fields"] = {}}, ["param1"] = 87, ["name"] = "wool:grey", ["x"] = 1, ["y"] = 9}, {["z"] = 11, ["meta"] = {["inventory"] = {}, ["fields"] = {}}, ["param1"] = 87, ["name"] = "wool:grey", ["x"] = 1, ["y"] = 9}, {["z"] = 12, ["meta"] = {["inventory"] = {}, ["fields"] = {}}, ["param1"] = 87, ["name"] = "wool:grey", ["x"] = 1, ["y"] = 9}, {["z"] = 13, ["meta"] = {["inventory"] = {}, ["fields"] = {}}, ["param1"] = 87, ["name"] = "wool:grey", ["x"] = 1, ["y"] = 9}, {["z"] = 14, ["meta"] = {["inventory"] = {}, ["fields"] = {}}, ["param1"] = 87, ["name"] = "wool:grey", ["x"] = 1, ["y"] = 9}, {["z"] = 15, ["meta"] = {["inventory"] = {}, ["fields"] = {}}, ["param1"] = 87, ["name"] = "wool:grey", ["x"] = 1, ["y"] = 9}, {["z"] = 0, ["meta"] = {["inventory"] = {}, ["fields"] = {}}, ["param1"] = 87, ["name"] = "wool:grey", ["x"] = 1, ["y"] = 10}, {["z"] = 1, ["meta"] = {["inventory"] = {}, ["fields"] = {}}, ["param1"] = 87, ["name"] = "wool:grey", ["x"] = 1, ["y"] = 10}, {["z"] = 14, ["meta"] = {["inventory"] = {}, ["fields"] = {}}, ["param1"] = 87, ["name"] = "wool:grey", ["x"] = 1, ["y"] = 10}, {["z"] = 15, ["meta"] = {["inventory"] = {}, ["fields"] = {}}, ["param1"] = 87, ["name"] = "wool:grey", ["x"] = 1, ["y"] = 10}, {["z"] = 0, ["meta"] = {["inventory"] = {}, ["fields"] = {}}, ["param1"] = 87, ["name"] = "wool:grey", ["x"] = 1, ["y"] = 11}, {["z"] = 1, ["meta"] = {["inventory"] = {}, ["fields"] = {}}, ["param1"] = 87, ["name"] = "wool:grey", ["x"] = 1, ["y"] = 11}, {["z"] = 14, ["meta"] = {["inventory"] = {}, ["fields"] = {}}, ["param1"] = 87, ["name"] = "wool:grey", ["x"] = 1, ["y"] = 11}, {["z"] = 15, ["meta"] = {["inventory"] = {}, ["fields"] = {}}, ["param1"] = 87, ["name"] = "wool:grey", ["x"] = 1, ["y"] = 11}, {["z"] = 0, ["meta"] = {["inventory"] = {}, ["fields"] = {}}, ["param1"] = 87, ["name"] = "wool:grey", ["x"] = 1, ["y"] = 12}, {["z"] = 1, ["meta"] = {["inventory"] = {}, ["fields"] = {}}, ["param1"] = 87, ["name"] = "wool:grey", ["x"] = 1, ["y"] = 12}, {["z"] = 14, ["meta"] = {["inventory"] = {}, ["fields"] = {}}, ["param1"] = 87, ["name"] = "wool:grey", ["x"] = 1, ["y"] = 12}, {["z"] = 15, ["meta"] = {["inventory"] = {}, ["fields"] = {}}, ["param1"] = 87, ["name"] = "wool:grey", ["x"] = 1, ["y"] = 12}, {["z"] = 0, ["meta"] = {["inventory"] = {}, ["fields"] = {}}, ["param1"] = 87, ["name"] = "wool:grey", ["x"] = 1, ["y"] = 13}, {["z"] = 1, ["meta"] = {["inventory"] = {}, ["fields"] = {}}, ["param1"] = 87, ["name"] = "wool:grey", ["x"] = 1, ["y"] = 13}, {["z"] = 14, ["meta"] = {["inventory"] = {}, ["fields"] = {}}, ["param1"] = 87, ["name"] = "wool:grey", ["x"] = 1, ["y"] = 13}, {["z"] = 15, ["meta"] = {["inventory"] = {}, ["fields"] = {}}, ["param1"] = 87, ["name"] = "wool:grey", ["x"] = 1, ["y"] = 13}, {["z"] = 0, ["meta"] = {["inventory"] = {}, ["fields"] = {}}, ["param1"] = 87, ["name"] = "wool:grey", ["x"] = 1, ["y"] = 14}, {["z"] = 1, ["meta"] = {["inventory"] = {}, ["fields"] = {}}, ["param1"] = 87, ["name"] = "wool:grey", ["x"] = 1, ["y"] = 14}, {["z"] = 14, ["meta"] = {["inventory"] = {}, ["fields"] = {}}, ["param1"] = 87, ["name"] = "wool:grey", ["x"] = 1, ["y"] = 14}, {["z"] = 15, ["meta"] = {["inventory"] = {}, ["fields"] = {}}, ["param1"] = 87, ["name"] = "wool:grey", ["x"] = 1, ["y"] = 14}, {["z"] = 0, ["meta"] = {["inventory"] = {}, ["fields"] = {}}, ["param1"] = 87, ["name"] = "wool:grey", ["x"] = 1, ["y"] = 15}, {["z"] = 1, ["meta"] = {["inventory"] = {}, ["fields"] = {}}, ["param1"] = 87, ["name"] = "wool:grey", ["x"] = 1, ["y"] = 15}, {["z"] = 14, ["meta"] = {["inventory"] = {}, ["fields"] = {}}, ["param1"] = 87, ["name"] = "wool:grey", ["x"] = 1, ["y"] = 15}, {["z"] = 15, ["meta"] = {["inventory"] = {}, ["fields"] = {}}, ["param1"] = 87, ["name"] = "wool:grey", ["x"] = 1, ["y"] = 15}, {["z"] = 0, ["meta"] = {["inventory"] = {}, ["fields"] = {}}, ["param1"] = 87, ["name"] = "wool:grey", ["x"] = 1, ["y"] = 16}, {["z"] = 1, ["meta"] = {["inventory"] = {}, ["fields"] = {}}, ["param1"] = 87, ["name"] = "wool:grey", ["x"] = 1, ["y"] = 16}, {["z"] = 14, ["meta"] = {["inventory"] = {}, ["fields"] = {}}, ["param1"] = 87, ["name"] = "wool:grey", ["x"] = 1, ["y"] = 16}, {["z"] = 15, ["meta"] = {["inventory"] = {}, ["fields"] = {}}, ["param1"] = 87, ["name"] = "wool:grey", ["x"] = 1, ["y"] = 16}, {["z"] = 0, ["meta"] = {["inventory"] = {}, ["fields"] = {}}, ["param1"] = 87, ["name"] = "wool:grey", ["x"] = 1, ["y"] = 17}, {["z"] = 1, ["meta"] = {["inventory"] = {}, ["fields"] = {}}, ["param1"] = 87, ["name"] = "wool:grey", ["x"] = 1, ["y"] = 17}, {["z"] = 14, ["meta"] = {["inventory"] = {}, ["fields"] = {}}, ["param1"] = 87, ["name"] = "wool:grey", ["x"] = 1, ["y"] = 17}, {["z"] = 15, ["meta"] = {["inventory"] = {}, ["fields"] = {}}, ["param1"] = 87, ["name"] = "wool:grey", ["x"] = 1, ["y"] = 17}, {["z"] = 0, ["meta"] = {["inventory"] = {}, ["fields"] = {}}, ["param1"] = 87, ["name"] = "wool:grey", ["x"] = 1, ["y"] = 18}, {["z"] = 1, ["meta"] = {["inventory"] = {}, ["fields"] = {}}, ["param1"] = 87, ["name"] = "wool:grey", ["x"] = 1, ["y"] = 18}, {["z"] = 14, ["meta"] = {["inventory"] = {}, ["fields"] = {}}, ["param1"] = 87, ["name"] = "wool:grey", ["x"] = 1, ["y"] = 18}, {["z"] = 15, ["meta"] = {["inventory"] = {}, ["fields"] = {}}, ["param1"] = 87, ["name"] = "wool:grey", ["x"] = 1, ["y"] = 18}, {["z"] = 0, ["meta"] = {["inventory"] = {}, ["fields"] = {}}, ["param1"] = 87, ["name"] = "wool:grey", ["x"] = 1, ["y"] = 19}, {["z"] = 1, ["meta"] = {["inventory"] = {}, ["fields"] = {}}, ["param1"] = 87, ["name"] = "wool:grey", ["x"] = 1, ["y"] = 19}, {["z"] = 14, ["meta"] = {["inventory"] = {}, ["fields"] = {}}, ["param1"] = 87, ["name"] = "wool:grey", ["x"] = 1, ["y"] = 19}, {["z"] = 15, ["meta"] = {["inventory"] = {}, ["fields"] = {}}, ["param1"] = 87, ["name"] = "wool:grey", ["x"] = 1, ["y"] = 19}, {["z"] = 0, ["meta"] = {["inventory"] = {}, ["fields"] = {}}, ["param1"] = 87, ["name"] = "wool:grey", ["x"] = 1, ["y"] = 20}, {["z"] = 1, ["meta"] = {["inventory"] = {}, ["fields"] = {}}, ["param1"] = 87, ["name"] = "wool:grey", ["x"] = 1, ["y"] = 20}, {["z"] = 14, ["meta"] = {["inventory"] = {}, ["fields"] = {}}, ["param1"] = 87, ["name"] = "wool:grey", ["x"] = 1, ["y"] = 20}, {["z"] = 15, ["meta"] = {["inventory"] = {}, ["fields"] = {}}, ["param1"] = 87, ["name"] = "wool:grey", ["x"] = 1, ["y"] = 20}, {["z"] = 0, ["meta"] = {["inventory"] = {}, ["fields"] = {}}, ["param1"] = 87, ["name"] = "wool:grey", ["x"] = 1, ["y"] = 21}, {["z"] = 1, ["meta"] = {["inventory"] = {}, ["fields"] = {}}, ["param1"] = 87, ["name"] = "wool:grey", ["x"] = 1, ["y"] = 21}, {["z"] = 14, ["meta"] = {["inventory"] = {}, ["fields"] = {}}, ["param1"] = 87, ["name"] = "wool:grey", ["x"] = 1, ["y"] = 21}, {["z"] = 15, ["meta"] = {["inventory"] = {}, ["fields"] = {}}, ["param1"] = 87, ["name"] = "wool:grey", ["x"] = 1, ["y"] = 21}, {["z"] = 0, ["meta"] = {["inventory"] = {}, ["fields"] = {}}, ["param1"] = 87, ["name"] = "wool:grey", ["x"] = 1, ["y"] = 22}, {["z"] = 1, ["meta"] = {["inventory"] = {}, ["fields"] = {}}, ["param1"] = 87, ["name"] = "wool:grey", ["x"] = 1, ["y"] = 22}, {["z"] = 2, ["meta"] = {["inventory"] = {}, ["fields"] = {}}, ["param1"] = 87, ["name"] = "wool:grey", ["x"] = 1, ["y"] = 22}, {["z"] = 3, ["meta"] = {["inventory"] = {}, ["fields"] = {}}, ["param1"] = 87, ["name"] = "wool:grey", ["x"] = 1, ["y"] = 22}, {["z"] = 4, ["meta"] = {["inventory"] = {}, ["fields"] = {}}, ["param1"] = 87, ["name"] = "wool:grey", ["x"] = 1, ["y"] = 22}, {["z"] = 5, ["meta"] = {["inventory"] = {}, ["fields"] = {}}, ["param1"] = 87, ["name"] = "wool:grey", ["x"] = 1, ["y"] = 22}, {["z"] = 6, ["meta"] = {["inventory"] = {}, ["fields"] = {}}, ["param1"] = 87, ["name"] = "wool:grey", ["x"] = 1, ["y"] = 22}, {["z"] = 7, ["meta"] = {["inventory"] = {}, ["fields"] = {}}, ["param1"] = 87, ["name"] = "wool:grey", ["x"] = 1, ["y"] = 22}, {["z"] = 8, ["meta"] = {["inventory"] = {}, ["fields"] = {}}, ["param1"] = 87, ["name"] = "wool:grey", ["x"] = 1, ["y"] = 22}, {["z"] = 9, ["meta"] = {["inventory"] = {}, ["fields"] = {}}, ["param1"] = 87, ["name"] = "wool:grey", ["x"] = 1, ["y"] = 22}, {["z"] = 10, ["meta"] = {["inventory"] = {}, ["fields"] = {}}, ["param1"] = 87, ["name"] = "wool:grey", ["x"] = 1, ["y"] = 22}, {["z"] = 11, ["meta"] = {["inventory"] = {}, ["fields"] = {}}, ["param1"] = 87, ["name"] = "wool:grey", ["x"] = 1, ["y"] = 22}, {["z"] = 12, ["meta"] = {["inventory"] = {}, ["fields"] = {}}, ["param1"] = 87, ["name"] = "wool:grey", ["x"] = 1, ["y"] = 22}, {["z"] = 13, ["meta"] = {["inventory"] = {}, ["fields"] = {}}, ["param1"] = 87, ["name"] = "wool:grey", ["x"] = 1, ["y"] = 22}, {["z"] = 14, ["meta"] = {["inventory"] = {}, ["fields"] = {}}, ["param1"] = 87, ["name"] = "wool:grey", ["x"] = 1, ["y"] = 22}, {["z"] = 15, ["meta"] = {["inventory"] = {}, ["fields"] = {}}, ["param1"] = 87, ["name"] = "wool:grey", ["x"] = 1, ["y"] = 22}, {["z"] = 0, ["meta"] = {["inventory"] = {}, ["fields"] = {}}, ["param1"] = 87, ["name"] = "wool:grey", ["x"] = 1, ["y"] = 23}, {["z"] = 1, ["meta"] = {["inventory"] = {}, ["fields"] = {}}, ["param1"] = 87, ["name"] = "wool:grey", ["x"] = 1, ["y"] = 23}, {["z"] = 6, ["meta"] = {["inventory"] = {}, ["fields"] = {}}, ["param1"] = 87, ["name"] = "wool:grey", ["x"] = 1, ["y"] = 23}, {["z"] = 9, ["meta"] = {["inventory"] = {}, ["fields"] = {}}, ["param1"] = 87, ["name"] = "wool:grey", ["x"] = 1, ["y"] = 23}, {["z"] = 14, ["meta"] = {["inventory"] = {}, ["fields"] = {}}, ["param1"] = 87, ["name"] = "wool:grey", ["x"] = 1, ["y"] = 23}, {["z"] = 15, ["meta"] = {["inventory"] = {}, ["fields"] = {}}, ["param1"] = 87, ["name"] = "wool:grey", ["x"] = 1, ["y"] = 23}, {["z"] = 0, ["meta"] = {["inventory"] = {}, ["fields"] = {}}, ["param1"] = 87, ["name"] = "wool:grey", ["x"] = 1, ["y"] = 24}, {["z"] = 1, ["meta"] = {["inventory"] = {}, ["fields"] = {}}, ["param1"] = 87, ["name"] = "wool:grey", ["x"] = 1, ["y"] = 24}, {["z"] = 6, ["meta"] = {["inventory"] = {}, ["fields"] = {}}, ["param1"] = 87, ["name"] = "wool:grey", ["x"] = 1, ["y"] = 24}, {["z"] = 9, ["meta"] = {["inventory"] = {}, ["fields"] = {}}, ["param1"] = 87, ["name"] = "wool:grey", ["x"] = 1, ["y"] = 24}, {["z"] = 14, ["meta"] = {["inventory"] = {}, ["fields"] = {}}, ["param1"] = 87, ["name"] = "wool:grey", ["x"] = 1, ["y"] = 24}, {["z"] = 15, ["meta"] = {["inventory"] = {}, ["fields"] = {}}, ["param1"] = 87, ["name"] = "wool:grey", ["x"] = 1, ["y"] = 24}, {["z"] = 0, ["meta"] = {["inventory"] = {}, ["fields"] = {}}, ["param1"] = 87, ["name"] = "wool:grey", ["x"] = 1, ["y"] = 25}, {["z"] = 1, ["meta"] = {["inventory"] = {}, ["fields"] = {}}, ["param1"] = 87, ["name"] = "wool:grey", ["x"] = 1, ["y"] = 25}, {["z"] = 2, ["meta"] = {["inventory"] = {}, ["fields"] = {}}, ["param1"] = 87, ["name"] = "wool:grey", ["x"] = 1, ["y"] = 25}, {["z"] = 3, ["meta"] = {["inventory"] = {}, ["fields"] = {}}, ["param1"] = 87, ["name"] = "wool:grey", ["x"] = 1, ["y"] = 25}, {["z"] = 4, ["meta"] = {["inventory"] = {}, ["fields"] = {}}, ["param1"] = 87, ["name"] = "wool:grey", ["x"] = 1, ["y"] = 25}, {["z"] = 5, ["meta"] = {["inventory"] = {}, ["fields"] = {}}, ["param1"] = 87, ["name"] = "wool:grey", ["x"] = 1, ["y"] = 25}, {["z"] = 6, ["meta"] = {["inventory"] = {}, ["fields"] = {}}, ["param1"] = 87, ["name"] = "wool:grey", ["x"] = 1, ["y"] = 25}, {["z"] = 7, ["meta"] = {["inventory"] = {}, ["fields"] = {}}, ["param1"] = 87, ["name"] = "wool:grey", ["x"] = 1, ["y"] = 25}, {["z"] = 8, ["meta"] = {["inventory"] = {}, ["fields"] = {}}, ["param1"] = 87, ["name"] = "wool:grey", ["x"] = 1, ["y"] = 25}, {["z"] = 9, ["meta"] = {["inventory"] = {}, ["fields"] = {}}, ["param1"] = 87, ["name"] = "wool:grey", ["x"] = 1, ["y"] = 25}, {["z"] = 10, ["meta"] = {["inventory"] = {}, ["fields"] = {}}, ["param1"] = 87, ["name"] = "wool:grey", ["x"] = 1, ["y"] = 25}, {["z"] = 11, ["meta"] = {["inventory"] = {}, ["fields"] = {}}, ["param1"] = 87, ["name"] = "wool:grey", ["x"] = 1, ["y"] = 25}, {["z"] = 12, ["meta"] = {["inventory"] = {}, ["fields"] = {}}, ["param1"] = 87, ["name"] = "wool:grey", ["x"] = 1, ["y"] = 25}, {["z"] = 13, ["meta"] = {["inventory"] = {}, ["fields"] = {}}, ["param1"] = 87, ["name"] = "wool:grey", ["x"] = 1, ["y"] = 25}, {["z"] = 14, ["meta"] = {["inventory"] = {}, ["fields"] = {}}, ["param1"] = 87, ["name"] = "wool:grey", ["x"] = 1, ["y"] = 25}, {["z"] = 15, ["meta"] = {["inventory"] = {}, ["fields"] = {}}, ["param1"] = 87, ["name"] = "wool:grey", ["x"] = 1, ["y"] = 25}, {["z"] = 0, ["meta"] = {["inventory"] = {}, ["fields"] = {}}, ["param1"] = 87, ["name"] = "wool:grey", ["x"] = 1, ["y"] = 26}, {["z"] = 1, ["meta"] = {["inventory"] = {}, ["fields"] = {}}, ["param1"] = 87, ["name"] = "wool:grey", ["x"] = 1, ["y"] = 26}, {["z"] = 14, ["meta"] = {["inventory"] = {}, ["fields"] = {}}, ["param1"] = 87, ["name"] = "wool:grey", ["x"] = 1, ["y"] = 26}, {["z"] = 15, ["meta"] = {["inventory"] = {}, ["fields"] = {}}, ["param1"] = 87, ["name"] = "wool:grey", ["x"] = 1, ["y"] = 26}, {["z"] = 0, ["meta"] = {["inventory"] = {}, ["fields"] = {}}, ["param1"] = 87, ["name"] = "wool:grey", ["x"] = 1, ["y"] = 27}, {["z"] = 1, ["meta"] = {["inventory"] = {}, ["fields"] = {}}, ["param1"] = 87, ["name"] = "wool:grey", ["x"] = 1, ["y"] = 27}, {["z"] = 14, ["meta"] = {["inventory"] = {}, ["fields"] = {}}, ["param1"] = 87, ["name"] = "wool:grey", ["x"] = 1, ["y"] = 27}, {["z"] = 15, ["meta"] = {["inventory"] = {}, ["fields"] = {}}, ["param1"] = 87, ["name"] = "wool:grey", ["x"] = 1, ["y"] = 27}, {["z"] = 0, ["meta"] = {["inventory"] = {}, ["fields"] = {}}, ["param1"] = 87, ["name"] = "wool:grey", ["x"] = 1, ["y"] = 28}, {["z"] = 1, ["meta"] = {["inventory"] = {}, ["fields"] = {}}, ["param1"] = 87, ["name"] = "wool:grey", ["x"] = 1, ["y"] = 28}, {["z"] = 14, ["meta"] = {["inventory"] = {}, ["fields"] = {}}, ["param1"] = 87, ["name"] = "wool:grey", ["x"] = 1, ["y"] = 28}, {["z"] = 15, ["meta"] = {["inventory"] = {}, ["fields"] = {}}, ["param1"] = 87, ["name"] = "wool:grey", ["x"] = 1, ["y"] = 28}, {["z"] = 0, ["meta"] = {["inventory"] = {}, ["fields"] = {}}, ["param1"] = 87, ["name"] = "wool:grey", ["x"] = 1, ["y"] = 29}, {["z"] = 1, ["meta"] = {["inventory"] = {}, ["fields"] = {}}, ["param1"] = 87, ["name"] = "wool:grey", ["x"] = 1, ["y"] = 29}, {["z"] = 14, ["meta"] = {["inventory"] = {}, ["fields"] = {}}, ["param1"] = 87, ["name"] = "wool:grey", ["x"] = 1, ["y"] = 29}, {["z"] = 15, ["meta"] = {["inventory"] = {}, ["fields"] = {}}, ["param1"] = 87, ["name"] = "wool:grey", ["x"] = 1, ["y"] = 29}, {["z"] = 0, ["meta"] = {["inventory"] = {}, ["fields"] = {}}, ["param1"] = 87, ["name"] = "wool:grey", ["x"] = 1, ["y"] = 30}, {["z"] = 1, ["meta"] = {["inventory"] = {}, ["fields"] = {}}, ["param1"] = 87, ["name"] = "wool:grey", ["x"] = 1, ["y"] = 30}, {["z"] = 14, ["meta"] = {["inventory"] = {}, ["fields"] = {}}, ["param1"] = 87, ["name"] = "wool:grey", ["x"] = 1, ["y"] = 30}, {["z"] = 15, ["meta"] = {["inventory"] = {}, ["fields"] = {}}, ["param1"] = 87, ["name"] = "wool:grey", ["x"] = 1, ["y"] = 30}, {["z"] = 0, ["meta"] = {["inventory"] = {}, ["fields"] = {}}, ["param1"] = 87, ["name"] = "wool:grey", ["x"] = 1, ["y"] = 31}, {["z"] = 1, ["meta"] = {["inventory"] = {}, ["fields"] = {}}, ["param1"] = 87, ["name"] = "wool:grey", ["x"] = 1, ["y"] = 31}, {["z"] = 14, ["meta"] = {["inventory"] = {}, ["fields"] = {}}, ["param1"] = 87, ["name"] = "wool:grey", ["x"] = 1, ["y"] = 31}, {["z"] = 15, ["meta"] = {["inventory"] = {}, ["fields"] = {}}, ["param1"] = 87, ["name"] = "wool:grey", ["x"] = 1, ["y"] = 31}, {["z"] = 14, ["meta"] = {["inventory"] = {}, ["fields"] = {}}, ["name"] = "wool:grey", ["x"] = 2, ["y"] = 5}, {["z"] = 1, ["meta"] = {["inventory"] = {}, ["fields"] = {}}, ["param1"] = 87, ["name"] = "wool:grey", ["x"] = 2, ["y"] = 6}, {["z"] = 7, ["meta"] = {["inventory"] = {}, ["fields"] = {}}, ["name"] = "default:steelblock", ["x"] = 2, ["y"] = 6}, {["z"] = 8, ["meta"] = {["inventory"] = {}, ["fields"] = {}}, ["name"] = "default:steelblock", ["x"] = 2, ["y"] = 6}, {["z"] = 9, ["meta"] = {["inventory"] = {}, ["fields"] = {}}, ["name"] = "default:steelblock", ["x"] = 2, ["y"] = 6}, {["z"] = 10, ["meta"] = {["inventory"] = {}, ["fields"] = {}}, ["name"] = "default:steelblock", ["x"] = 2, ["y"] = 6}, {["z"] = 11, ["meta"] = {["inventory"] = {}, ["fields"] = {}}, ["name"] = "default:steelblock", ["x"] = 2, ["y"] = 6}, {["z"] = 12, ["meta"] = {["inventory"] = {}, ["fields"] = {}}, ["name"] = "default:steelblock", ["x"] = 2, ["y"] = 6}, {["z"] = 13, ["meta"] = {["inventory"] = {}, ["fields"] = {}}, ["name"] = "default:steelblock", ["x"] = 2, ["y"] = 6}, {["z"] = 7, ["meta"] = {["inventory"] = {}, ["fields"] = {}}, ["name"] = "default:steelblock", ["x"] = 2, ["y"] = 7}, {["z"] = 8, ["meta"] = {["inventory"] = {}, ["fields"] = {}}, ["name"] = "default:steelblock", ["x"] = 2, ["y"] = 7}, {["z"] = 9, ["meta"] = {["inventory"] = {}, ["fields"] = {}}, ["name"] = "default:steelblock", ["x"] = 2, ["y"] = 7}, {["z"] = 10, ["meta"] = {["inventory"] = {}, ["fields"] = {}}, ["name"] = "default:steelblock", ["x"] = 2, ["y"] = 7}, {["z"] = 11, ["meta"] = {["inventory"] = {}, ["fields"] = {}}, ["name"] = "default:steelblock", ["x"] = 2, ["y"] = 7}, {["z"] = 12, ["meta"] = {["inventory"] = {}, ["fields"] = {}}, ["name"] = "default:steelblock", ["x"] = 2, ["y"] = 7}, {["z"] = 13, ["meta"] = {["inventory"] = {}, ["fields"] = {}}, ["name"] = "default:steelblock", ["x"] = 2, ["y"] = 7}, {["z"] = 7, ["meta"] = {["inventory"] = {}, ["fields"] = {}}, ["name"] = "default:steelblock", ["x"] = 2, ["y"] = 8}, {["z"] = 8, ["meta"] = {["inventory"] = {}, ["fields"] = {}}, ["name"] = "default:steelblock", ["x"] = 2, ["y"] = 8}, {["z"] = 9, ["meta"] = {["inventory"] = {}, ["fields"] = {}}, ["name"] = "default:steelblock", ["x"] = 2, ["y"] = 8}, {["z"] = 10, ["meta"] = {["inventory"] = {}, ["fields"] = {}}, ["name"] = "default:steelblock", ["x"] = 2, ["y"] = 8}, {["z"] = 11, ["meta"] = {["inventory"] = {}, ["fields"] = {}}, ["name"] = "default:steelblock", ["x"] = 2, ["y"] = 8}, {["z"] = 12, ["meta"] = {["inventory"] = {}, ["fields"] = {}}, ["name"] = "default:steelblock", ["x"] = 2, ["y"] = 8}, {["z"] = 13, ["meta"] = {["inventory"] = {}, ["fields"] = {}}, ["name"] = "default:steelblock", ["x"] = 2, ["y"] = 8}, {["z"] = 1, ["meta"] = {["inventory"] = {}, ["fields"] = {}}, ["param1"] = 87, ["name"] = "wool:grey", ["x"] = 2, ["y"] = 9}, {["z"] = 7, ["meta"] = {["inventory"] = {}, ["fields"] = {}}, ["name"] = "default:steelblock", ["x"] = 2, ["y"] = 9}, {["z"] = 8, ["meta"] = {["inventory"] = {}, ["fields"] = {}}, ["name"] = "default:steelblock", ["x"] = 2, ["y"] = 9}, {["z"] = 9, ["meta"] = {["inventory"] = {}, ["fields"] = {}}, ["name"] = "default:steelblock", ["x"] = 2, ["y"] = 9}, {["z"] = 10, ["meta"] = {["inventory"] = {}, ["fields"] = {}}, ["name"] = "default:steelblock", ["x"] = 2, ["y"] = 9}, {["z"] = 11, ["meta"] = {["inventory"] = {}, ["fields"] = {}}, ["name"] = "default:steelblock", ["x"] = 2, ["y"] = 9}, {["z"] = 12, ["meta"] = {["inventory"] = {}, ["fields"] = {}}, ["name"] = "default:steelblock", ["x"] = 2, ["y"] = 9}, {["z"] = 13, ["meta"] = {["inventory"] = {}, ["fields"] = {}}, ["name"] = "default:steelblock", ["x"] = 2, ["y"] = 9}, {["z"] = 14, ["meta"] = {["inventory"] = {}, ["fields"] = {}}, ["name"] = "wool:grey", ["x"] = 2, ["y"] = 10}, {["z"] = 14, ["name"] = "wool:grey", ["x"] = 2, ["y"] = 19}, {["z"] = 1, ["meta"] = {["inventory"] = {}, ["fields"] = {}}, ["param1"] = 87, ["name"] = "wool:grey", ["x"] = 2, ["y"] = 22}, {["z"] = 7, ["meta"] = {["inventory"] = {}, ["fields"] = {}}, ["param1"] = 82, ["name"] = "default:steelblock", ["x"] = 2, ["y"] = 22}, {["z"] = 8, ["meta"] = {["inventory"] = {}, ["fields"] = {}}, ["param1"] = 82, ["name"] = "default:steelblock", ["x"] = 2, ["y"] = 22}, {["z"] = 9, ["meta"] = {["inventory"] = {}, ["fields"] = {}}, ["param1"] = 82, ["name"] = "default:steelblock", ["x"] = 2, ["y"] = 22}, {["z"] = 10, ["meta"] = {["inventory"] = {}, ["fields"] = {}}, ["param1"] = 82, ["name"] = "default:steelblock", ["x"] = 2, ["y"] = 22}, {["z"] = 11, ["meta"] = {["inventory"] = {}, ["fields"] = {}}, ["param1"] = 82, ["name"] = "default:steelblock", ["x"] = 2, ["y"] = 22}, {["z"] = 12, ["meta"] = {["inventory"] = {}, ["fields"] = {}}, ["param1"] = 82, ["name"] = "default:steelblock", ["x"] = 2, ["y"] = 22}, {["z"] = 13, ["meta"] = {["inventory"] = {}, ["fields"] = {}}, ["param1"] = 82, ["name"] = "default:steelblock", ["x"] = 2, ["y"] = 22}, {["z"] = 14, ["meta"] = {["inventory"] = {}, ["fields"] = {}}, ["name"] = "wool:grey", ["x"] = 2, ["y"] = 22}, {["z"] = 7, ["meta"] = {["inventory"] = {}, ["fields"] = {}}, ["param1"] = 82, ["name"] = "default:steelblock", ["x"] = 2, ["y"] = 23}, {["z"] = 8, ["meta"] = {["inventory"] = {}, ["fields"] = {}}, ["param1"] = 82, ["name"] = "default:steelblock", ["x"] = 2, ["y"] = 23}, {["z"] = 9, ["meta"] = {["inventory"] = {}, ["fields"] = {}}, ["param1"] = 82, ["name"] = "default:steelblock", ["x"] = 2, ["y"] = 23}, {["z"] = 10, ["meta"] = {["inventory"] = {}, ["fields"] = {}}, ["param1"] = 82, ["name"] = "default:steelblock", ["x"] = 2, ["y"] = 23}, {["z"] = 11, ["meta"] = {["inventory"] = {}, ["fields"] = {}}, ["param1"] = 82, ["name"] = "default:steelblock", ["x"] = 2, ["y"] = 23}, {["z"] = 12, ["meta"] = {["inventory"] = {}, ["fields"] = {}}, ["param1"] = 82, ["name"] = "default:steelblock", ["x"] = 2, ["y"] = 23}, {["z"] = 13, ["meta"] = {["inventory"] = {}, ["fields"] = {}}, ["param1"] = 82, ["name"] = "default:steelblock", ["x"] = 2, ["y"] = 23}, {["z"] = 7, ["meta"] = {["inventory"] = {}, ["fields"] = {}}, ["param1"] = 82, ["name"] = "default:steelblock", ["x"] = 2, ["y"] = 24}, {["z"] = 8, ["meta"] = {["inventory"] = {}, ["fields"] = {}}, ["param1"] = 82, ["name"] = "default:steelblock", ["x"] = 2, ["y"] = 24}, {["z"] = 9, ["meta"] = {["inventory"] = {}, ["fields"] = {}}, ["param1"] = 82, ["name"] = "default:steelblock", ["x"] = 2, ["y"] = 24}, {["z"] = 10, ["meta"] = {["inventory"] = {}, ["fields"] = {}}, ["param1"] = 82, ["name"] = "default:steelblock", ["x"] = 2, ["y"] = 24}, {["z"] = 11, ["meta"] = {["inventory"] = {}, ["fields"] = {}}, ["param1"] = 82, ["name"] = "default:steelblock", ["x"] = 2, ["y"] = 24}, {["z"] = 12, ["meta"] = {["inventory"] = {}, ["fields"] = {}}, ["param1"] = 82, ["name"] = "default:steelblock", ["x"] = 2, ["y"] = 24}, {["z"] = 13, ["meta"] = {["inventory"] = {}, ["fields"] = {}}, ["param1"] = 82, ["name"] = "default:steelblock", ["x"] = 2, ["y"] = 24}, {["z"] = 1, ["meta"] = {["inventory"] = {}, ["fields"] = {}}, ["param1"] = 87, ["name"] = "wool:grey", ["x"] = 2, ["y"] = 25}, {["z"] = 7, ["meta"] = {["inventory"] = {}, ["fields"] = {}}, ["param1"] = 82, ["name"] = "default:steelblock", ["x"] = 2, ["y"] = 25}, {["z"] = 8, ["meta"] = {["inventory"] = {}, ["fields"] = {}}, ["param1"] = 82, ["name"] = "default:steelblock", ["x"] = 2, ["y"] = 25}, {["z"] = 9, ["meta"] = {["inventory"] = {}, ["fields"] = {}}, ["param1"] = 82, ["name"] = "default:steelblock", ["x"] = 2, ["y"] = 25}, {["z"] = 10, ["meta"] = {["inventory"] = {}, ["fields"] = {}}, ["param1"] = 82, ["name"] = "default:steelblock", ["x"] = 2, ["y"] = 25}, {["z"] = 11, ["meta"] = {["inventory"] = {}, ["fields"] = {}}, ["param1"] = 82, ["name"] = "default:steelblock", ["x"] = 2, ["y"] = 25}, {["z"] = 12, ["meta"] = {["inventory"] = {}, ["fields"] = {}}, ["param1"] = 82, ["name"] = "default:steelblock", ["x"] = 2, ["y"] = 25}, {["z"] = 13, ["meta"] = {["inventory"] = {}, ["fields"] = {}}, ["param1"] = 82, ["name"] = "default:steelblock", ["x"] = 2, ["y"] = 25}, {["z"] = 14, ["meta"] = {["inventory"] = {}, ["fields"] = {}}, ["param1"] = 87, ["name"] = "wool:grey", ["x"] = 2, ["y"] = 25}, {["z"] = 14, ["name"] = "wool:grey", ["x"] = 2, ["y"] = 28}, {["z"] = 7, ["meta"] = {["inventory"] = {}, ["fields"] = {}}, ["name"] = "default:steelblock", ["x"] = 3, ["y"] = 4}, {["z"] = 8, ["meta"] = {["inventory"] = {}, ["fields"] = {}}, ["name"] = "default:steelblock", ["x"] = 3, ["y"] = 4}, {["z"] = 9, ["meta"] = {["inventory"] = {}, ["fields"] = {}}, ["name"] = "default:steelblock", ["x"] = 3, ["y"] = 4}, {["z"] = 10, ["meta"] = {["inventory"] = {}, ["fields"] = {}}, ["name"] = "default:steelblock", ["x"] = 3, ["y"] = 4}, {["z"] = 11, ["meta"] = {["inventory"] = {}, ["fields"] = {}}, ["name"] = "default:steelblock", ["x"] = 3, ["y"] = 4}, {["z"] = 12, ["meta"] = {["inventory"] = {}, ["fields"] = {}}, ["name"] = "default:steelblock", ["x"] = 3, ["y"] = 4}, {["z"] = 13, ["meta"] = {["inventory"] = {}, ["fields"] = {}}, ["name"] = "default:steelblock", ["x"] = 3, ["y"] = 4}, {["z"] = 7, ["meta"] = {["inventory"] = {}, ["fields"] = {}}, ["name"] = "default:steelblock", ["x"] = 3, ["y"] = 5}, {["z"] = 8, ["meta"] = {["inventory"] = {}, ["fields"] = {}}, ["name"] = "default:steelblock", ["x"] = 3, ["y"] = 5}, {["z"] = 9, ["meta"] = {["inventory"] = {}, ["fields"] = {}}, ["name"] = "default:steelblock", ["x"] = 3, ["y"] = 5}, {["z"] = 10, ["meta"] = {["inventory"] = {}, ["fields"] = {}}, ["name"] = "default:steelblock", ["x"] = 3, ["y"] = 5}, {["z"] = 11, ["meta"] = {["inventory"] = {}, ["fields"] = {}}, ["name"] = "default:steelblock", ["x"] = 3, ["y"] = 5}, {["z"] = 12, ["meta"] = {["inventory"] = {}, ["fields"] = {}}, ["name"] = "default:steelblock", ["x"] = 3, ["y"] = 5}, {["z"] = 13, ["meta"] = {["inventory"] = {}, ["fields"] = {}}, ["name"] = "default:steelblock", ["x"] = 3, ["y"] = 5}, {["z"] = 14, ["meta"] = {["inventory"] = {}, ["fields"] = {}}, ["name"] = "wool:grey", ["x"] = 3, ["y"] = 5}, {["z"] = 1, ["meta"] = {["inventory"] = {}, ["fields"] = {}}, ["param1"] = 87, ["name"] = "wool:grey", ["x"] = 3, ["y"] = 6}, {["z"] = 7, ["meta"] = {["inventory"] = {}, ["fields"] = {}}, ["name"] = "default:steelblock", ["x"] = 3, ["y"] = 6}, {["z"] = 8, ["meta"] = {["inventory"] = {}, ["fields"] = {}}, ["name"] = "default:steelblock", ["x"] = 3, ["y"] = 6}, {["z"] = 9, ["meta"] = {["inventory"] = {}, ["fields"] = {}}, ["name"] = "default:steelblock", ["x"] = 3, ["y"] = 6}, {["z"] = 10, ["meta"] = {["inventory"] = {}, ["fields"] = {}}, ["name"] = "default:steelblock", ["x"] = 3, ["y"] = 6}, {["z"] = 11, ["meta"] = {["inventory"] = {}, ["fields"] = {}}, ["name"] = "default:steelblock", ["x"] = 3, ["y"] = 6}, {["z"] = 12, ["meta"] = {["inventory"] = {}, ["fields"] = {}}, ["name"] = "default:steelblock", ["x"] = 3, ["y"] = 6}, {["z"] = 13, ["meta"] = {["inventory"] = {}, ["fields"] = {}}, ["name"] = "default:steelblock", ["x"] = 3, ["y"] = 6}, {["z"] = 7, ["meta"] = {["inventory"] = {}, ["fields"] = {}}, ["name"] = "default:steelblock", ["x"] = 3, ["y"] = 7}, {["z"] = 8, ["meta"] = {["inventory"] = {}, ["fields"] = {}}, ["name"] = "default:steelblock", ["x"] = 3, ["y"] = 7}, {["z"] = 9, ["meta"] = {["inventory"] = {}, ["fields"] = {}}, ["name"] = "default:steelblock", ["x"] = 3, ["y"] = 7}, {["z"] = 10, ["meta"] = {["inventory"] = {}, ["fields"] = {}}, ["name"] = "default:steelblock", ["x"] = 3, ["y"] = 7}, {["z"] = 11, ["meta"] = {["inventory"] = {}, ["fields"] = {}}, ["name"] = "default:steelblock", ["x"] = 3, ["y"] = 7}, {["z"] = 12, ["meta"] = {["inventory"] = {}, ["fields"] = {}}, ["name"] = "default:steelblock", ["x"] = 3, ["y"] = 7}, {["z"] = 13, ["meta"] = {["inventory"] = {}, ["fields"] = {}}, ["name"] = "default:steelblock", ["x"] = 3, ["y"] = 7}, {["z"] = 7, ["meta"] = {["inventory"] = {}, ["fields"] = {}}, ["name"] = "default:steelblock", ["x"] = 3, ["y"] = 8}, {["z"] = 8, ["meta"] = {["inventory"] = {}, ["fields"] = {}}, ["name"] = "default:steelblock", ["x"] = 3, ["y"] = 8}, {["z"] = 9, ["meta"] = {["inventory"] = {}, ["fields"] = {}}, ["name"] = "default:steelblock", ["x"] = 3, ["y"] = 8}, {["z"] = 10, ["meta"] = {["inventory"] = {}, ["fields"] = {}}, ["name"] = "default:steelblock", ["x"] = 3, ["y"] = 8}, {["z"] = 11, ["meta"] = {["inventory"] = {}, ["fields"] = {}}, ["name"] = "default:steelblock", ["x"] = 3, ["y"] = 8}, {["z"] = 12, ["meta"] = {["inventory"] = {}, ["fields"] = {}}, ["name"] = "default:steelblock", ["x"] = 3, ["y"] = 8}, {["z"] = 13, ["meta"] = {["inventory"] = {}, ["fields"] = {}}, ["name"] = "default:steelblock", ["x"] = 3, ["y"] = 8}, {["z"] = 1, ["meta"] = {["inventory"] = {}, ["fields"] = {}}, ["param1"] = 87, ["name"] = "wool:grey", ["x"] = 3, ["y"] = 9}, {["z"] = 7, ["meta"] = {["inventory"] = {}, ["fields"] = {}}, ["name"] = "default:steelblock", ["x"] = 3, ["y"] = 9}, {["z"] = 8, ["meta"] = {["inventory"] = {}, ["fields"] = {}}, ["name"] = "default:steelblock", ["x"] = 3, ["y"] = 9}, {["z"] = 9, ["meta"] = {["inventory"] = {}, ["fields"] = {}}, ["name"] = "default:steelblock", ["x"] = 3, ["y"] = 9}, {["z"] = 10, ["meta"] = {["inventory"] = {}, ["fields"] = {}}, ["name"] = "default:steelblock", ["x"] = 3, ["y"] = 9}, {["z"] = 11, ["meta"] = {["inventory"] = {}, ["fields"] = {}}, ["name"] = "default:steelblock", ["x"] = 3, ["y"] = 9}, {["z"] = 12, ["meta"] = {["inventory"] = {}, ["fields"] = {}}, ["name"] = "default:steelblock", ["x"] = 3, ["y"] = 9}, {["z"] = 13, ["meta"] = {["inventory"] = {}, ["fields"] = {}}, ["name"] = "default:steelblock", ["x"] = 3, ["y"] = 9}, {["z"] = 7, ["meta"] = {["inventory"] = {}, ["fields"] = {}}, ["name"] = "default:steelblock", ["x"] = 3, ["y"] = 10}, {["z"] = 8, ["meta"] = {["inventory"] = {}, ["fields"] = {}}, ["name"] = "default:steelblock", ["x"] = 3, ["y"] = 10}, {["z"] = 9, ["meta"] = {["inventory"] = {}, ["fields"] = {}}, ["name"] = "default:steelblock", ["x"] = 3, ["y"] = 10}, {["z"] = 10, ["meta"] = {["inventory"] = {}, ["fields"] = {}}, ["name"] = "default:steelblock", ["x"] = 3, ["y"] = 10}, {["z"] = 11, ["meta"] = {["inventory"] = {}, ["fields"] = {}}, ["name"] = "default:steelblock", ["x"] = 3, ["y"] = 10}, {["z"] = 12, ["meta"] = {["inventory"] = {}, ["fields"] = {}}, ["name"] = "default:steelblock", ["x"] = 3, ["y"] = 10}, {["z"] = 13, ["meta"] = {["inventory"] = {}, ["fields"] = {}}, ["name"] = "default:steelblock", ["x"] = 3, ["y"] = 10}, {["z"] = 14, ["meta"] = {["inventory"] = {}, ["fields"] = {}}, ["name"] = "wool:grey", ["x"] = 3, ["y"] = 10}, {["z"] = 7, ["meta"] = {["inventory"] = {}, ["fields"] = {}}, ["name"] = "default:steelblock", ["x"] = 3, ["y"] = 11}, {["z"] = 8, ["meta"] = {["inventory"] = {}, ["fields"] = {}}, ["name"] = "default:steelblock", ["x"] = 3, ["y"] = 11}, {["z"] = 9, ["meta"] = {["inventory"] = {}, ["fields"] = {}}, ["name"] = "default:steelblock", ["x"] = 3, ["y"] = 11}, {["z"] = 10, ["meta"] = {["inventory"] = {}, ["fields"] = {}}, ["name"] = "default:steelblock", ["x"] = 3, ["y"] = 11}, {["z"] = 11, ["meta"] = {["inventory"] = {}, ["fields"] = {}}, ["name"] = "default:steelblock", ["x"] = 3, ["y"] = 11}, {["z"] = 12, ["meta"] = {["inventory"] = {}, ["fields"] = {}}, ["name"] = "default:steelblock", ["x"] = 3, ["y"] = 11}, {["z"] = 13, ["meta"] = {["inventory"] = {}, ["fields"] = {}}, ["name"] = "default:steelblock", ["x"] = 3, ["y"] = 11}, {["z"] = 14, ["name"] = "wool:grey", ["x"] = 3, ["y"] = 19}, {["z"] = 7, ["meta"] = {["inventory"] = {}, ["fields"] = {}}, ["param1"] = 82, ["name"] = "default:steelblock", ["x"] = 3, ["y"] = 20}, {["z"] = 8, ["meta"] = {["inventory"] = {}, ["fields"] = {}}, ["param1"] = 82, ["name"] = "default:steelblock", ["x"] = 3, ["y"] = 20}, {["z"] = 9, ["meta"] = {["inventory"] = {}, ["fields"] = {}}, ["param1"] = 82, ["name"] = "default:steelblock", ["x"] = 3, ["y"] = 20}, {["z"] = 10, ["meta"] = {["inventory"] = {}, ["fields"] = {}}, ["param1"] = 82, ["name"] = "default:steelblock", ["x"] = 3, ["y"] = 20}, {["z"] = 11, ["meta"] = {["inventory"] = {}, ["fields"] = {}}, ["param1"] = 82, ["name"] = "default:steelblock", ["x"] = 3, ["y"] = 20}, {["z"] = 12, ["meta"] = {["inventory"] = {}, ["fields"] = {}}, ["param1"] = 82, ["name"] = "default:steelblock", ["x"] = 3, ["y"] = 20}, {["z"] = 13, ["meta"] = {["inventory"] = {}, ["fields"] = {}}, ["param1"] = 82, ["name"] = "default:steelblock", ["x"] = 3, ["y"] = 20}, {["z"] = 14, ["name"] = "wool:grey", ["x"] = 3, ["y"] = 20}, {["z"] = 7, ["meta"] = {["inventory"] = {}, ["fields"] = {}}, ["param1"] = 82, ["name"] = "default:steelblock", ["x"] = 3, ["y"] = 21}, {["z"] = 8, ["meta"] = {["inventory"] = {}, ["fields"] = {}}, ["param1"] = 82, ["name"] = "default:steelblock", ["x"] = 3, ["y"] = 21}, {["z"] = 9, ["meta"] = {["inventory"] = {}, ["fields"] = {}}, ["param1"] = 82, ["name"] = "default:steelblock", ["x"] = 3, ["y"] = 21}, {["z"] = 10, ["meta"] = {["inventory"] = {}, ["fields"] = {}}, ["param1"] = 82, ["name"] = "default:steelblock", ["x"] = 3, ["y"] = 21}, {["z"] = 11, ["meta"] = {["inventory"] = {}, ["fields"] = {}}, ["param1"] = 82, ["name"] = "default:steelblock", ["x"] = 3, ["y"] = 21}, {["z"] = 12, ["meta"] = {["inventory"] = {}, ["fields"] = {}}, ["param1"] = 82, ["name"] = "default:steelblock", ["x"] = 3, ["y"] = 21}, {["z"] = 13, ["meta"] = {["inventory"] = {}, ["fields"] = {}}, ["param1"] = 82, ["name"] = "default:steelblock", ["x"] = 3, ["y"] = 21}, {["z"] = 14, ["name"] = "wool:grey", ["x"] = 3, ["y"] = 21}, {["z"] = 1, ["meta"] = {["inventory"] = {}, ["fields"] = {}}, ["param1"] = 87, ["name"] = "wool:grey", ["x"] = 3, ["y"] = 22}, {["z"] = 7, ["meta"] = {["inventory"] = {}, ["fields"] = {}}, ["param1"] = 82, ["name"] = "default:steelblock", ["x"] = 3, ["y"] = 22}, {["z"] = 8, ["meta"] = {["inventory"] = {}, ["fields"] = {}}, ["param1"] = 82, ["name"] = "default:steelblock", ["x"] = 3, ["y"] = 22}, {["z"] = 9, ["meta"] = {["inventory"] = {}, ["fields"] = {}}, ["param1"] = 82, ["name"] = "default:steelblock", ["x"] = 3, ["y"] = 22}, {["z"] = 10, ["meta"] = {["inventory"] = {}, ["fields"] = {}}, ["param1"] = 82, ["name"] = "default:steelblock", ["x"] = 3, ["y"] = 22}, {["z"] = 11, ["meta"] = {["inventory"] = {}, ["fields"] = {}}, ["param1"] = 82, ["name"] = "default:steelblock", ["x"] = 3, ["y"] = 22}, {["z"] = 12, ["meta"] = {["inventory"] = {}, ["fields"] = {}}, ["param1"] = 82, ["name"] = "default:steelblock", ["x"] = 3, ["y"] = 22}, {["z"] = 13, ["meta"] = {["inventory"] = {}, ["fields"] = {}}, ["param1"] = 82, ["name"] = "default:steelblock", ["x"] = 3, ["y"] = 22}, {["z"] = 14, ["name"] = "wool:grey", ["x"] = 3, ["y"] = 22}, {["z"] = 7, ["meta"] = {["inventory"] = {}, ["fields"] = {}}, ["param1"] = 82, ["name"] = "default:steelblock", ["x"] = 3, ["y"] = 23}, {["z"] = 8, ["meta"] = {["inventory"] = {}, ["fields"] = {}}, ["param1"] = 82, ["name"] = "default:steelblock", ["x"] = 3, ["y"] = 23}, {["z"] = 9, ["meta"] = {["inventory"] = {}, ["fields"] = {}}, ["param1"] = 82, ["name"] = "default:steelblock", ["x"] = 3, ["y"] = 23}, {["z"] = 10, ["meta"] = {["inventory"] = {}, ["fields"] = {}}, ["param1"] = 82, ["name"] = "default:steelblock", ["x"] = 3, ["y"] = 23}, {["z"] = 11, ["meta"] = {["inventory"] = {}, ["fields"] = {}}, ["param1"] = 82, ["name"] = "default:steelblock", ["x"] = 3, ["y"] = 23}, {["z"] = 12, ["meta"] = {["inventory"] = {}, ["fields"] = {}}, ["param1"] = 82, ["name"] = "default:steelblock", ["x"] = 3, ["y"] = 23}, {["z"] = 13, ["meta"] = {["inventory"] = {}, ["fields"] = {}}, ["param1"] = 82, ["name"] = "default:steelblock", ["x"] = 3, ["y"] = 23}, {["z"] = 14, ["name"] = "wool:grey", ["x"] = 3, ["y"] = 23}, {["z"] = 7, ["meta"] = {["inventory"] = {}, ["fields"] = {}}, ["param1"] = 82, ["name"] = "default:steelblock", ["x"] = 3, ["y"] = 24}, {["z"] = 8, ["meta"] = {["inventory"] = {}, ["fields"] = {}}, ["param1"] = 82, ["name"] = "default:steelblock", ["x"] = 3, ["y"] = 24}, {["z"] = 9, ["meta"] = {["inventory"] = {}, ["fields"] = {}}, ["param1"] = 82, ["name"] = "default:steelblock", ["x"] = 3, ["y"] = 24}, {["z"] = 10, ["meta"] = {["inventory"] = {}, ["fields"] = {}}, ["param1"] = 82, ["name"] = "default:steelblock", ["x"] = 3, ["y"] = 24}, {["z"] = 11, ["meta"] = {["inventory"] = {}, ["fields"] = {}}, ["param1"] = 82, ["name"] = "default:steelblock", ["x"] = 3, ["y"] = 24}, {["z"] = 12, ["meta"] = {["inventory"] = {}, ["fields"] = {}}, ["param1"] = 82, ["name"] = "default:steelblock", ["x"] = 3, ["y"] = 24}, {["z"] = 13, ["meta"] = {["inventory"] = {}, ["fields"] = {}}, ["param1"] = 82, ["name"] = "default:steelblock", ["x"] = 3, ["y"] = 24}, {["z"] = 14, ["name"] = "wool:grey", ["x"] = 3, ["y"] = 24}, {["z"] = 1, ["meta"] = {["inventory"] = {}, ["fields"] = {}}, ["param1"] = 87, ["name"] = "wool:grey", ["x"] = 3, ["y"] = 25}, {["z"] = 7, ["meta"] = {["inventory"] = {}, ["fields"] = {}}, ["param1"] = 82, ["name"] = "default:steelblock", ["x"] = 3, ["y"] = 25}, {["z"] = 8, ["meta"] = {["inventory"] = {}, ["fields"] = {}}, ["param1"] = 82, ["name"] = "default:steelblock", ["x"] = 3, ["y"] = 25}, {["z"] = 9, ["meta"] = {["inventory"] = {}, ["fields"] = {}}, ["param1"] = 82, ["name"] = "default:steelblock", ["x"] = 3, ["y"] = 25}, {["z"] = 10, ["meta"] = {["inventory"] = {}, ["fields"] = {}}, ["param1"] = 82, ["name"] = "default:steelblock", ["x"] = 3, ["y"] = 25}, {["z"] = 11, ["meta"] = {["inventory"] = {}, ["fields"] = {}}, ["param1"] = 82, ["name"] = "default:steelblock", ["x"] = 3, ["y"] = 25}, {["z"] = 12, ["meta"] = {["inventory"] = {}, ["fields"] = {}}, ["param1"] = 82, ["name"] = "default:steelblock", ["x"] = 3, ["y"] = 25}, {["z"] = 13, ["meta"] = {["inventory"] = {}, ["fields"] = {}}, ["param1"] = 82, ["name"] = "default:steelblock", ["x"] = 3, ["y"] = 25}, {["z"] = 14, ["name"] = "wool:grey", ["x"] = 3, ["y"] = 25}, {["z"] = 7, ["meta"] = {["inventory"] = {}, ["fields"] = {}}, ["param1"] = 82, ["name"] = "default:steelblock", ["x"] = 3, ["y"] = 26}, {["z"] = 8, ["meta"] = {["inventory"] = {}, ["fields"] = {}}, ["param1"] = 82, ["name"] = "default:steelblock", ["x"] = 3, ["y"] = 26}, {["z"] = 9, ["meta"] = {["inventory"] = {}, ["fields"] = {}}, ["param1"] = 82, ["name"] = "default:steelblock", ["x"] = 3, ["y"] = 26}, {["z"] = 10, ["meta"] = {["inventory"] = {}, ["fields"] = {}}, ["param1"] = 82, ["name"] = "default:steelblock", ["x"] = 3, ["y"] = 26}, {["z"] = 11, ["meta"] = {["inventory"] = {}, ["fields"] = {}}, ["param1"] = 82, ["name"] = "default:steelblock", ["x"] = 3, ["y"] = 26}, {["z"] = 12, ["meta"] = {["inventory"] = {}, ["fields"] = {}}, ["param1"] = 82, ["name"] = "default:steelblock", ["x"] = 3, ["y"] = 26}, {["z"] = 13, ["meta"] = {["inventory"] = {}, ["fields"] = {}}, ["param1"] = 82, ["name"] = "default:steelblock", ["x"] = 3, ["y"] = 26}, {["z"] = 14, ["name"] = "wool:grey", ["x"] = 3, ["y"] = 26}, {["z"] = 7, ["meta"] = {["inventory"] = {}, ["fields"] = {}}, ["param1"] = 82, ["name"] = "default:steelblock", ["x"] = 3, ["y"] = 27}, {["z"] = 8, ["meta"] = {["inventory"] = {}, ["fields"] = {}}, ["param1"] = 82, ["name"] = "default:steelblock", ["x"] = 3, ["y"] = 27}, {["z"] = 9, ["meta"] = {["inventory"] = {}, ["fields"] = {}}, ["param1"] = 82, ["name"] = "default:steelblock", ["x"] = 3, ["y"] = 27}, {["z"] = 10, ["meta"] = {["inventory"] = {}, ["fields"] = {}}, ["param1"] = 82, ["name"] = "default:steelblock", ["x"] = 3, ["y"] = 27}, {["z"] = 11, ["meta"] = {["inventory"] = {}, ["fields"] = {}}, ["param1"] = 82, ["name"] = "default:steelblock", ["x"] = 3, ["y"] = 27}, {["z"] = 12, ["meta"] = {["inventory"] = {}, ["fields"] = {}}, ["param1"] = 82, ["name"] = "default:steelblock", ["x"] = 3, ["y"] = 27}, {["z"] = 13, ["meta"] = {["inventory"] = {}, ["fields"] = {}}, ["param1"] = 82, ["name"] = "default:steelblock", ["x"] = 3, ["y"] = 27}, {["z"] = 14, ["name"] = "wool:grey", ["x"] = 3, ["y"] = 27}, {["z"] = 14, ["name"] = "wool:grey", ["x"] = 3, ["y"] = 28}, {["z"] = 7, ["meta"] = {["inventory"] = {}, ["fields"] = {}}, ["name"] = "default:steelblock", ["x"] = 4, ["y"] = 3}, {["z"] = 8, ["meta"] = {["inventory"] = {}, ["fields"] = {}}, ["name"] = "default:steelblock", ["x"] = 4, ["y"] = 3}, {["z"] = 9, ["meta"] = {["inventory"] = {}, ["fields"] = {}}, ["name"] = "default:steelblock", ["x"] = 4, ["y"] = 3}, {["z"] = 10, ["meta"] = {["inventory"] = {}, ["fields"] = {}}, ["name"] = "default:steelblock", ["x"] = 4, ["y"] = 3}, {["z"] = 11, ["meta"] = {["inventory"] = {}, ["fields"] = {}}, ["name"] = "default:steelblock", ["x"] = 4, ["y"] = 3}, {["z"] = 12, ["meta"] = {["inventory"] = {}, ["fields"] = {}}, ["name"] = "default:steelblock", ["x"] = 4, ["y"] = 3}, {["z"] = 13, ["meta"] = {["inventory"] = {}, ["fields"] = {}}, ["name"] = "default:steelblock", ["x"] = 4, ["y"] = 3}, {["z"] = 7, ["meta"] = {["inventory"] = {}, ["fields"] = {}}, ["name"] = "default:steelblock", ["x"] = 4, ["y"] = 4}, {["z"] = 8, ["meta"] = {["inventory"] = {}, ["fields"] = {}}, ["name"] = "default:steelblock", ["x"] = 4, ["y"] = 4}, {["z"] = 9, ["meta"] = {["inventory"] = {}, ["fields"] = {}}, ["name"] = "default:steelblock", ["x"] = 4, ["y"] = 4}, {["z"] = 10, ["meta"] = {["inventory"] = {}, ["fields"] = {}}, ["name"] = "default:steelblock", ["x"] = 4, ["y"] = 4}, {["z"] = 11, ["meta"] = {["inventory"] = {}, ["fields"] = {}}, ["name"] = "default:steelblock", ["x"] = 4, ["y"] = 4}, {["z"] = 12, ["meta"] = {["inventory"] = {}, ["fields"] = {}}, ["name"] = "default:steelblock", ["x"] = 4, ["y"] = 4}, {["z"] = 13, ["meta"] = {["inventory"] = {}, ["fields"] = {}}, ["name"] = "default:steelblock", ["x"] = 4, ["y"] = 4}, {["z"] = 7, ["meta"] = {["inventory"] = {}, ["fields"] = {}}, ["name"] = "default:steelblock", ["x"] = 4, ["y"] = 5}, {["z"] = 8, ["meta"] = {["inventory"] = {}, ["fields"] = {}}, ["name"] = "default:steelblock", ["x"] = 4, ["y"] = 5}, {["z"] = 9, ["meta"] = {["inventory"] = {}, ["fields"] = {}}, ["name"] = "default:steelblock", ["x"] = 4, ["y"] = 5}, {["z"] = 10, ["meta"] = {["inventory"] = {}, ["fields"] = {}}, ["name"] = "default:steelblock", ["x"] = 4, ["y"] = 5}, {["z"] = 11, ["meta"] = {["inventory"] = {}, ["fields"] = {}}, ["name"] = "default:steelblock", ["x"] = 4, ["y"] = 5}, {["z"] = 12, ["meta"] = {["inventory"] = {}, ["fields"] = {}}, ["name"] = "default:steelblock", ["x"] = 4, ["y"] = 5}, {["z"] = 13, ["meta"] = {["inventory"] = {}, ["fields"] = {}}, ["name"] = "default:steelblock", ["x"] = 4, ["y"] = 5}, {["z"] = 14, ["meta"] = {["inventory"] = {}, ["fields"] = {}}, ["name"] = "wool:grey", ["x"] = 4, ["y"] = 5}, {["z"] = 1, ["meta"] = {["inventory"] = {}, ["fields"] = {}}, ["param1"] = 87, ["name"] = "wool:grey", ["x"] = 4, ["y"] = 6}, {["z"] = 2, ["meta"] = {["inventory"] = {}, ["fields"] = {}}, ["param1"] = 82, ["name"] = "default:steelblock", ["x"] = 4, ["y"] = 6}, {["z"] = 3, ["meta"] = {["inventory"] = {}, ["fields"] = {}}, ["param1"] = 82, ["name"] = "default:steelblock", ["x"] = 4, ["y"] = 6}, {["z"] = 4, ["meta"] = {["inventory"] = {}, ["fields"] = {}}, ["param1"] = 82, ["name"] = "default:steelblock", ["x"] = 4, ["y"] = 6}, {["z"] = 5, ["meta"] = {["inventory"] = {}, ["fields"] = {}}, ["param1"] = 82, ["name"] = "default:steelblock", ["x"] = 4, ["y"] = 6}, {["z"] = 6, ["meta"] = {["inventory"] = {}, ["fields"] = {}}, ["param1"] = 82, ["name"] = "default:steelblock", ["x"] = 4, ["y"] = 6}, {["z"] = 7, ["meta"] = {["inventory"] = {}, ["fields"] = {}}, ["param1"] = 82, ["name"] = "default:steelblock", ["x"] = 4, ["y"] = 6}, {["z"] = 8, ["meta"] = {["inventory"] = {}, ["fields"] = {}}, ["param1"] = 82, ["name"] = "default:steelblock", ["x"] = 4, ["y"] = 6}, {["z"] = 9, ["meta"] = {["inventory"] = {}, ["fields"] = {}}, ["param1"] = 82, ["name"] = "default:steelblock", ["x"] = 4, ["y"] = 6}, {["z"] = 10, ["meta"] = {["inventory"] = {}, ["fields"] = {}}, ["param1"] = 82, ["name"] = "default:steelblock", ["x"] = 4, ["y"] = 6}, {["z"] = 11, ["meta"] = {["inventory"] = {}, ["fields"] = {}}, ["param1"] = 82, ["name"] = "default:steelblock", ["x"] = 4, ["y"] = 6}, {["z"] = 12, ["meta"] = {["inventory"] = {}, ["fields"] = {}}, ["param1"] = 82, ["name"] = "default:steelblock", ["x"] = 4, ["y"] = 6}, {["z"] = 13, ["meta"] = {["inventory"] = {}, ["fields"] = {}}, ["param1"] = 82, ["name"] = "default:steelblock", ["x"] = 4, ["y"] = 6}, {["z"] = 2, ["meta"] = {["inventory"] = {}, ["fields"] = {}}, ["param1"] = 82, ["name"] = "default:steelblock", ["x"] = 4, ["y"] = 7}, {["z"] = 3, ["meta"] = {["inventory"] = {}, ["fields"] = {}}, ["param1"] = 82, ["name"] = "default:steelblock", ["x"] = 4, ["y"] = 7}, {["z"] = 4, ["meta"] = {["inventory"] = {}, ["fields"] = {}}, ["param1"] = 82, ["name"] = "default:steelblock", ["x"] = 4, ["y"] = 7}, {["z"] = 5, ["meta"] = {["inventory"] = {}, ["fields"] = {}}, ["param1"] = 82, ["name"] = "default:steelblock", ["x"] = 4, ["y"] = 7}, {["z"] = 6, ["meta"] = {["inventory"] = {}, ["fields"] = {}}, ["param1"] = 82, ["name"] = "default:steelblock", ["x"] = 4, ["y"] = 7}, {["z"] = 7, ["meta"] = {["inventory"] = {}, ["fields"] = {}}, ["param1"] = 82, ["name"] = "default:steelblock", ["x"] = 4, ["y"] = 7}, {["z"] = 8, ["meta"] = {["inventory"] = {}, ["fields"] = {}}, ["param1"] = 82, ["name"] = "default:steelblock", ["x"] = 4, ["y"] = 7}, {["z"] = 9, ["meta"] = {["inventory"] = {}, ["fields"] = {}}, ["param1"] = 82, ["name"] = "default:steelblock", ["x"] = 4, ["y"] = 7}, {["z"] = 10, ["meta"] = {["inventory"] = {}, ["fields"] = {}}, ["param1"] = 82, ["name"] = "default:steelblock", ["x"] = 4, ["y"] = 7}, {["z"] = 11, ["meta"] = {["inventory"] = {}, ["fields"] = {}}, ["param1"] = 82, ["name"] = "default:steelblock", ["x"] = 4, ["y"] = 7}, {["z"] = 12, ["meta"] = {["inventory"] = {}, ["fields"] = {}}, ["param1"] = 82, ["name"] = "default:steelblock", ["x"] = 4, ["y"] = 7}, {["z"] = 13, ["meta"] = {["inventory"] = {}, ["fields"] = {}}, ["param1"] = 82, ["name"] = "default:steelblock", ["x"] = 4, ["y"] = 7}, {["z"] = 2, ["meta"] = {["inventory"] = {}, ["fields"] = {}}, ["param1"] = 82, ["name"] = "default:steelblock", ["x"] = 4, ["y"] = 8}, {["z"] = 3, ["meta"] = {["inventory"] = {}, ["fields"] = {}}, ["param1"] = 82, ["name"] = "default:steelblock", ["x"] = 4, ["y"] = 8}, {["z"] = 4, ["meta"] = {["inventory"] = {}, ["fields"] = {}}, ["param1"] = 82, ["name"] = "default:steelblock", ["x"] = 4, ["y"] = 8}, {["z"] = 5, ["meta"] = {["inventory"] = {}, ["fields"] = {}}, ["param1"] = 82, ["name"] = "default:steelblock", ["x"] = 4, ["y"] = 8}, {["z"] = 6, ["meta"] = {["inventory"] = {}, ["fields"] = {}}, ["param1"] = 82, ["name"] = "default:steelblock", ["x"] = 4, ["y"] = 8}, {["z"] = 7, ["meta"] = {["inventory"] = {}, ["fields"] = {}}, ["param1"] = 82, ["name"] = "default:steelblock", ["x"] = 4, ["y"] = 8}, {["z"] = 8, ["meta"] = {["inventory"] = {}, ["fields"] = {}}, ["param1"] = 82, ["name"] = "default:steelblock", ["x"] = 4, ["y"] = 8}, {["z"] = 9, ["meta"] = {["inventory"] = {}, ["fields"] = {}}, ["param1"] = 82, ["name"] = "default:steelblock", ["x"] = 4, ["y"] = 8}, {["z"] = 10, ["meta"] = {["inventory"] = {}, ["fields"] = {}}, ["param1"] = 82, ["name"] = "default:steelblock", ["x"] = 4, ["y"] = 8}, {["z"] = 11, ["meta"] = {["inventory"] = {}, ["fields"] = {}}, ["param1"] = 82, ["name"] = "default:steelblock", ["x"] = 4, ["y"] = 8}, {["z"] = 12, ["meta"] = {["inventory"] = {}, ["fields"] = {}}, ["param1"] = 82, ["name"] = "default:steelblock", ["x"] = 4, ["y"] = 8}, {["z"] = 13, ["meta"] = {["inventory"] = {}, ["fields"] = {}}, ["param1"] = 82, ["name"] = "default:steelblock", ["x"] = 4, ["y"] = 8}, {["z"] = 1, ["meta"] = {["inventory"] = {}, ["fields"] = {}}, ["param1"] = 87, ["name"] = "wool:grey", ["x"] = 4, ["y"] = 9}, {["z"] = 2, ["meta"] = {["inventory"] = {}, ["fields"] = {}}, ["param1"] = 82, ["name"] = "default:steelblock", ["x"] = 4, ["y"] = 9}, {["z"] = 3, ["meta"] = {["inventory"] = {}, ["fields"] = {}}, ["param1"] = 82, ["name"] = "default:steelblock", ["x"] = 4, ["y"] = 9}, {["z"] = 4, ["meta"] = {["inventory"] = {}, ["fields"] = {}}, ["param1"] = 82, ["name"] = "default:steelblock", ["x"] = 4, ["y"] = 9}, {["z"] = 5, ["meta"] = {["inventory"] = {}, ["fields"] = {}}, ["param1"] = 82, ["name"] = "default:steelblock", ["x"] = 4, ["y"] = 9}, {["z"] = 6, ["meta"] = {["inventory"] = {}, ["fields"] = {}}, ["param1"] = 82, ["name"] = "default:steelblock", ["x"] = 4, ["y"] = 9}, {["z"] = 7, ["meta"] = {["inventory"] = {}, ["fields"] = {}}, ["param1"] = 82, ["name"] = "default:steelblock", ["x"] = 4, ["y"] = 9}, {["z"] = 8, ["meta"] = {["inventory"] = {}, ["fields"] = {}}, ["param1"] = 82, ["name"] = "default:steelblock", ["x"] = 4, ["y"] = 9}, {["z"] = 9, ["meta"] = {["inventory"] = {}, ["fields"] = {}}, ["param1"] = 82, ["name"] = "default:steelblock", ["x"] = 4, ["y"] = 9}, {["z"] = 10, ["meta"] = {["inventory"] = {}, ["fields"] = {}}, ["param1"] = 82, ["name"] = "default:steelblock", ["x"] = 4, ["y"] = 9}, {["z"] = 11, ["meta"] = {["inventory"] = {}, ["fields"] = {}}, ["param1"] = 82, ["name"] = "default:steelblock", ["x"] = 4, ["y"] = 9}, {["z"] = 12, ["meta"] = {["inventory"] = {}, ["fields"] = {}}, ["param1"] = 82, ["name"] = "default:steelblock", ["x"] = 4, ["y"] = 9}, {["z"] = 13, ["meta"] = {["inventory"] = {}, ["fields"] = {}}, ["param1"] = 82, ["name"] = "default:steelblock", ["x"] = 4, ["y"] = 9}, {["z"] = 7, ["meta"] = {["inventory"] = {}, ["fields"] = {}}, ["name"] = "default:steelblock", ["x"] = 4, ["y"] = 10}, {["z"] = 8, ["meta"] = {["inventory"] = {}, ["fields"] = {}}, ["name"] = "default:steelblock", ["x"] = 4, ["y"] = 10}, {["z"] = 9, ["meta"] = {["inventory"] = {}, ["fields"] = {}}, ["name"] = "default:steelblock", ["x"] = 4, ["y"] = 10}, {["z"] = 10, ["meta"] = {["inventory"] = {}, ["fields"] = {}}, ["name"] = "default:steelblock", ["x"] = 4, ["y"] = 10}, {["z"] = 11, ["meta"] = {["inventory"] = {}, ["fields"] = {}}, ["name"] = "default:steelblock", ["x"] = 4, ["y"] = 10}, {["z"] = 12, ["meta"] = {["inventory"] = {}, ["fields"] = {}}, ["name"] = "default:steelblock", ["x"] = 4, ["y"] = 10}, {["z"] = 13, ["meta"] = {["inventory"] = {}, ["fields"] = {}}, ["name"] = "default:steelblock", ["x"] = 4, ["y"] = 10}, {["z"] = 14, ["meta"] = {["inventory"] = {}, ["fields"] = {}}, ["name"] = "wool:grey", ["x"] = 4, ["y"] = 10}, {["z"] = 7, ["meta"] = {["inventory"] = {}, ["fields"] = {}}, ["name"] = "default:steelblock", ["x"] = 4, ["y"] = 11}, {["z"] = 8, ["meta"] = {["inventory"] = {}, ["fields"] = {}}, ["name"] = "default:steelblock", ["x"] = 4, ["y"] = 11}, {["z"] = 9, ["meta"] = {["inventory"] = {}, ["fields"] = {}}, ["name"] = "default:steelblock", ["x"] = 4, ["y"] = 11}, {["z"] = 10, ["meta"] = {["inventory"] = {}, ["fields"] = {}}, ["name"] = "default:steelblock", ["x"] = 4, ["y"] = 11}, {["z"] = 11, ["meta"] = {["inventory"] = {}, ["fields"] = {}}, ["name"] = "default:steelblock", ["x"] = 4, ["y"] = 11}, {["z"] = 12, ["meta"] = {["inventory"] = {}, ["fields"] = {}}, ["name"] = "default:steelblock", ["x"] = 4, ["y"] = 11}, {["z"] = 13, ["meta"] = {["inventory"] = {}, ["fields"] = {}}, ["name"] = "default:steelblock", ["x"] = 4, ["y"] = 11}, {["z"] = 7, ["meta"] = {["inventory"] = {}, ["fields"] = {}}, ["name"] = "default:steelblock", ["x"] = 4, ["y"] = 12}, {["z"] = 8, ["meta"] = {["inventory"] = {}, ["fields"] = {}}, ["name"] = "default:steelblock", ["x"] = 4, ["y"] = 12}, {["z"] = 9, ["meta"] = {["inventory"] = {}, ["fields"] = {}}, ["name"] = "default:steelblock", ["x"] = 4, ["y"] = 12}, {["z"] = 10, ["meta"] = {["inventory"] = {}, ["fields"] = {}}, ["name"] = "default:steelblock", ["x"] = 4, ["y"] = 12}, {["z"] = 11, ["meta"] = {["inventory"] = {}, ["fields"] = {}}, ["name"] = "default:steelblock", ["x"] = 4, ["y"] = 12}, {["z"] = 12, ["meta"] = {["inventory"] = {}, ["fields"] = {}}, ["name"] = "default:steelblock", ["x"] = 4, ["y"] = 12}, {["z"] = 13, ["meta"] = {["inventory"] = {}, ["fields"] = {}}, ["name"] = "default:steelblock", ["x"] = 4, ["y"] = 12}, {["z"] = 7, ["meta"] = {["inventory"] = {}, ["fields"] = {}}, ["param1"] = 82, ["name"] = "default:steelblock", ["x"] = 4, ["y"] = 19}, {["z"] = 8, ["meta"] = {["inventory"] = {}, ["fields"] = {}}, ["param1"] = 82, ["name"] = "default:steelblock", ["x"] = 4, ["y"] = 19}, {["z"] = 9, ["meta"] = {["inventory"] = {}, ["fields"] = {}}, ["param1"] = 82, ["name"] = "default:steelblock", ["x"] = 4, ["y"] = 19}, {["z"] = 10, ["meta"] = {["inventory"] = {}, ["fields"] = {}}, ["param1"] = 82, ["name"] = "default:steelblock", ["x"] = 4, ["y"] = 19}, {["z"] = 11, ["meta"] = {["inventory"] = {}, ["fields"] = {}}, ["param1"] = 82, ["name"] = "default:steelblock", ["x"] = 4, ["y"] = 19}, {["z"] = 12, ["meta"] = {["inventory"] = {}, ["fields"] = {}}, ["param1"] = 82, ["name"] = "default:steelblock", ["x"] = 4, ["y"] = 19}, {["z"] = 13, ["meta"] = {["inventory"] = {}, ["fields"] = {}}, ["param1"] = 82, ["name"] = "default:steelblock", ["x"] = 4, ["y"] = 19}, {["z"] = 14, ["name"] = "wool:grey", ["x"] = 4, ["y"] = 19}, {["z"] = 7, ["meta"] = {["inventory"] = {}, ["fields"] = {}}, ["param1"] = 82, ["name"] = "default:steelblock", ["x"] = 4, ["y"] = 20}, {["z"] = 8, ["meta"] = {["inventory"] = {}, ["fields"] = {}}, ["param1"] = 82, ["name"] = "default:steelblock", ["x"] = 4, ["y"] = 20}, {["z"] = 9, ["meta"] = {["inventory"] = {}, ["fields"] = {}}, ["param1"] = 82, ["name"] = "default:steelblock", ["x"] = 4, ["y"] = 20}, {["z"] = 10, ["meta"] = {["inventory"] = {}, ["fields"] = {}}, ["param1"] = 82, ["name"] = "default:steelblock", ["x"] = 4, ["y"] = 20}, {["z"] = 11, ["meta"] = {["inventory"] = {}, ["fields"] = {}}, ["param1"] = 82, ["name"] = "default:steelblock", ["x"] = 4, ["y"] = 20}, {["z"] = 12, ["meta"] = {["inventory"] = {}, ["fields"] = {}}, ["param1"] = 82, ["name"] = "default:steelblock", ["x"] = 4, ["y"] = 20}, {["z"] = 13, ["meta"] = {["inventory"] = {}, ["fields"] = {}}, ["param1"] = 82, ["name"] = "default:steelblock", ["x"] = 4, ["y"] = 20}, {["z"] = 14, ["name"] = "wool:grey", ["x"] = 4, ["y"] = 20}, {["z"] = 7, ["meta"] = {["inventory"] = {}, ["fields"] = {}}, ["param1"] = 82, ["name"] = "default:steelblock", ["x"] = 4, ["y"] = 21}, {["z"] = 8, ["meta"] = {["inventory"] = {}, ["fields"] = {}}, ["param1"] = 82, ["name"] = "default:steelblock", ["x"] = 4, ["y"] = 21}, {["z"] = 9, ["meta"] = {["inventory"] = {}, ["fields"] = {}}, ["param1"] = 82, ["name"] = "default:steelblock", ["x"] = 4, ["y"] = 21}, {["z"] = 10, ["meta"] = {["inventory"] = {}, ["fields"] = {}}, ["param1"] = 82, ["name"] = "default:steelblock", ["x"] = 4, ["y"] = 21}, {["z"] = 11, ["meta"] = {["inventory"] = {}, ["fields"] = {}}, ["param1"] = 82, ["name"] = "default:steelblock", ["x"] = 4, ["y"] = 21}, {["z"] = 12, ["meta"] = {["inventory"] = {}, ["fields"] = {}}, ["param1"] = 82, ["name"] = "default:steelblock", ["x"] = 4, ["y"] = 21}, {["z"] = 13, ["meta"] = {["inventory"] = {}, ["fields"] = {}}, ["param1"] = 82, ["name"] = "default:steelblock", ["x"] = 4, ["y"] = 21}, {["z"] = 1, ["meta"] = {["inventory"] = {}, ["fields"] = {}}, ["param1"] = 87, ["name"] = "wool:grey", ["x"] = 4, ["y"] = 22}, {["z"] = 2, ["meta"] = {["inventory"] = {}, ["fields"] = {}}, ["param1"] = 82, ["name"] = "default:steelblock", ["x"] = 4, ["y"] = 22}, {["z"] = 3, ["meta"] = {["inventory"] = {}, ["fields"] = {}}, ["param1"] = 82, ["name"] = "default:steelblock", ["x"] = 4, ["y"] = 22}, {["z"] = 4, ["meta"] = {["inventory"] = {}, ["fields"] = {}}, ["param1"] = 82, ["name"] = "default:steelblock", ["x"] = 4, ["y"] = 22}, {["z"] = 5, ["meta"] = {["inventory"] = {}, ["fields"] = {}}, ["param1"] = 82, ["name"] = "default:steelblock", ["x"] = 4, ["y"] = 22}, {["z"] = 6, ["meta"] = {["inventory"] = {}, ["fields"] = {}}, ["param1"] = 82, ["name"] = "default:steelblock", ["x"] = 4, ["y"] = 22}, {["z"] = 7, ["meta"] = {["inventory"] = {}, ["fields"] = {}}, ["param1"] = 82, ["name"] = "default:steelblock", ["x"] = 4, ["y"] = 22}, {["z"] = 8, ["meta"] = {["inventory"] = {}, ["fields"] = {}}, ["param1"] = 82, ["name"] = "default:steelblock", ["x"] = 4, ["y"] = 22}, {["z"] = 9, ["meta"] = {["inventory"] = {}, ["fields"] = {}}, ["param1"] = 82, ["name"] = "default:steelblock", ["x"] = 4, ["y"] = 22}, {["z"] = 10, ["meta"] = {["inventory"] = {}, ["fields"] = {}}, ["param1"] = 82, ["name"] = "default:steelblock", ["x"] = 4, ["y"] = 22}, {["z"] = 11, ["meta"] = {["inventory"] = {}, ["fields"] = {}}, ["param1"] = 82, ["name"] = "default:steelblock", ["x"] = 4, ["y"] = 22}, {["z"] = 12, ["meta"] = {["inventory"] = {}, ["fields"] = {}}, ["param1"] = 82, ["name"] = "default:steelblock", ["x"] = 4, ["y"] = 22}, {["z"] = 13, ["meta"] = {["inventory"] = {}, ["fields"] = {}}, ["param1"] = 82, ["name"] = "default:steelblock", ["x"] = 4, ["y"] = 22}, {["z"] = 2, ["meta"] = {["inventory"] = {}, ["fields"] = {}}, ["param1"] = 82, ["name"] = "default:steelblock", ["x"] = 4, ["y"] = 23}, {["z"] = 3, ["meta"] = {["inventory"] = {}, ["fields"] = {}}, ["param1"] = 82, ["name"] = "default:steelblock", ["x"] = 4, ["y"] = 23}, {["z"] = 4, ["meta"] = {["inventory"] = {}, ["fields"] = {}}, ["param1"] = 82, ["name"] = "default:steelblock", ["x"] = 4, ["y"] = 23}, {["z"] = 5, ["meta"] = {["inventory"] = {}, ["fields"] = {}}, ["param1"] = 82, ["name"] = "default:steelblock", ["x"] = 4, ["y"] = 23}, {["z"] = 6, ["meta"] = {["inventory"] = {}, ["fields"] = {}}, ["param1"] = 82, ["name"] = "default:steelblock", ["x"] = 4, ["y"] = 23}, {["z"] = 7, ["meta"] = {["inventory"] = {}, ["fields"] = {}}, ["param1"] = 82, ["name"] = "default:steelblock", ["x"] = 4, ["y"] = 23}, {["z"] = 8, ["meta"] = {["inventory"] = {}, ["fields"] = {}}, ["param1"] = 82, ["name"] = "default:steelblock", ["x"] = 4, ["y"] = 23}, {["z"] = 9, ["meta"] = {["inventory"] = {}, ["fields"] = {}}, ["param1"] = 82, ["name"] = "default:steelblock", ["x"] = 4, ["y"] = 23}, {["z"] = 10, ["meta"] = {["inventory"] = {}, ["fields"] = {}}, ["param1"] = 82, ["name"] = "default:steelblock", ["x"] = 4, ["y"] = 23}, {["z"] = 11, ["meta"] = {["inventory"] = {}, ["fields"] = {}}, ["param1"] = 82, ["name"] = "default:steelblock", ["x"] = 4, ["y"] = 23}, {["z"] = 12, ["meta"] = {["inventory"] = {}, ["fields"] = {}}, ["param1"] = 82, ["name"] = "default:steelblock", ["x"] = 4, ["y"] = 23}, {["z"] = 13, ["meta"] = {["inventory"] = {}, ["fields"] = {}}, ["param1"] = 82, ["name"] = "default:steelblock", ["x"] = 4, ["y"] = 23}, {["z"] = 2, ["meta"] = {["inventory"] = {}, ["fields"] = {}}, ["param1"] = 82, ["name"] = "default:steelblock", ["x"] = 4, ["y"] = 24}, {["z"] = 3, ["meta"] = {["inventory"] = {}, ["fields"] = {}}, ["param1"] = 82, ["name"] = "default:steelblock", ["x"] = 4, ["y"] = 24}, {["z"] = 4, ["meta"] = {["inventory"] = {}, ["fields"] = {}}, ["param1"] = 82, ["name"] = "default:steelblock", ["x"] = 4, ["y"] = 24}, {["z"] = 5, ["meta"] = {["inventory"] = {}, ["fields"] = {}}, ["param1"] = 82, ["name"] = "default:steelblock", ["x"] = 4, ["y"] = 24}, {["z"] = 6, ["meta"] = {["inventory"] = {}, ["fields"] = {}}, ["param1"] = 82, ["name"] = "default:steelblock", ["x"] = 4, ["y"] = 24}, {["z"] = 7, ["meta"] = {["inventory"] = {}, ["fields"] = {}}, ["param1"] = 82, ["name"] = "default:steelblock", ["x"] = 4, ["y"] = 24}, {["z"] = 8, ["meta"] = {["inventory"] = {}, ["fields"] = {}}, ["param1"] = 82, ["name"] = "default:steelblock", ["x"] = 4, ["y"] = 24}, {["z"] = 9, ["meta"] = {["inventory"] = {}, ["fields"] = {}}, ["param1"] = 82, ["name"] = "default:steelblock", ["x"] = 4, ["y"] = 24}, {["z"] = 10, ["meta"] = {["inventory"] = {}, ["fields"] = {}}, ["param1"] = 82, ["name"] = "default:steelblock", ["x"] = 4, ["y"] = 24}, {["z"] = 11, ["meta"] = {["inventory"] = {}, ["fields"] = {}}, ["param1"] = 82, ["name"] = "default:steelblock", ["x"] = 4, ["y"] = 24}, {["z"] = 12, ["meta"] = {["inventory"] = {}, ["fields"] = {}}, ["param1"] = 82, ["name"] = "default:steelblock", ["x"] = 4, ["y"] = 24}, {["z"] = 13, ["meta"] = {["inventory"] = {}, ["fields"] = {}}, ["param1"] = 82, ["name"] = "default:steelblock", ["x"] = 4, ["y"] = 24}, {["z"] = 1, ["meta"] = {["inventory"] = {}, ["fields"] = {}}, ["param1"] = 87, ["name"] = "wool:grey", ["x"] = 4, ["y"] = 25}, {["z"] = 2, ["meta"] = {["inventory"] = {}, ["fields"] = {}}, ["param1"] = 82, ["name"] = "default:steelblock", ["x"] = 4, ["y"] = 25}, {["z"] = 3, ["meta"] = {["inventory"] = {}, ["fields"] = {}}, ["param1"] = 82, ["name"] = "default:steelblock", ["x"] = 4, ["y"] = 25}, {["z"] = 4, ["meta"] = {["inventory"] = {}, ["fields"] = {}}, ["param1"] = 82, ["name"] = "default:steelblock", ["x"] = 4, ["y"] = 25}, {["z"] = 5, ["meta"] = {["inventory"] = {}, ["fields"] = {}}, ["param1"] = 82, ["name"] = "default:steelblock", ["x"] = 4, ["y"] = 25}, {["z"] = 6, ["meta"] = {["inventory"] = {}, ["fields"] = {}}, ["param1"] = 82, ["name"] = "default:steelblock", ["x"] = 4, ["y"] = 25}, {["z"] = 7, ["meta"] = {["inventory"] = {}, ["fields"] = {}}, ["param1"] = 82, ["name"] = "default:steelblock", ["x"] = 4, ["y"] = 25}, {["z"] = 8, ["meta"] = {["inventory"] = {}, ["fields"] = {}}, ["param1"] = 82, ["name"] = "default:steelblock", ["x"] = 4, ["y"] = 25}, {["z"] = 9, ["meta"] = {["inventory"] = {}, ["fields"] = {}}, ["param1"] = 82, ["name"] = "default:steelblock", ["x"] = 4, ["y"] = 25}, {["z"] = 10, ["meta"] = {["inventory"] = {}, ["fields"] = {}}, ["param1"] = 82, ["name"] = "default:steelblock", ["x"] = 4, ["y"] = 25}, {["z"] = 11, ["meta"] = {["inventory"] = {}, ["fields"] = {}}, ["param1"] = 82, ["name"] = "default:steelblock", ["x"] = 4, ["y"] = 25}, {["z"] = 12, ["meta"] = {["inventory"] = {}, ["fields"] = {}}, ["param1"] = 82, ["name"] = "default:steelblock", ["x"] = 4, ["y"] = 25}, {["z"] = 13, ["meta"] = {["inventory"] = {}, ["fields"] = {}}, ["param1"] = 82, ["name"] = "default:steelblock", ["x"] = 4, ["y"] = 25}, {["z"] = 7, ["meta"] = {["inventory"] = {}, ["fields"] = {}}, ["param1"] = 82, ["name"] = "default:steelblock", ["x"] = 4, ["y"] = 26}, {["z"] = 8, ["meta"] = {["inventory"] = {}, ["fields"] = {}}, ["param1"] = 82, ["name"] = "default:steelblock", ["x"] = 4, ["y"] = 26}, {["z"] = 9, ["meta"] = {["inventory"] = {}, ["fields"] = {}}, ["param1"] = 82, ["name"] = "default:steelblock", ["x"] = 4, ["y"] = 26}, {["z"] = 10, ["meta"] = {["inventory"] = {}, ["fields"] = {}}, ["param1"] = 82, ["name"] = "default:steelblock", ["x"] = 4, ["y"] = 26}, {["z"] = 11, ["meta"] = {["inventory"] = {}, ["fields"] = {}}, ["param1"] = 82, ["name"] = "default:steelblock", ["x"] = 4, ["y"] = 26}, {["z"] = 12, ["meta"] = {["inventory"] = {}, ["fields"] = {}}, ["param1"] = 82, ["name"] = "default:steelblock", ["x"] = 4, ["y"] = 26}, {["z"] = 13, ["meta"] = {["inventory"] = {}, ["fields"] = {}}, ["param1"] = 82, ["name"] = "default:steelblock", ["x"] = 4, ["y"] = 26}, {["z"] = 7, ["meta"] = {["inventory"] = {}, ["fields"] = {}}, ["param1"] = 82, ["name"] = "default:steelblock", ["x"] = 4, ["y"] = 27}, {["z"] = 8, ["meta"] = {["inventory"] = {}, ["fields"] = {}}, ["param1"] = 82, ["name"] = "default:steelblock", ["x"] = 4, ["y"] = 27}, {["z"] = 9, ["meta"] = {["inventory"] = {}, ["fields"] = {}}, ["param1"] = 82, ["name"] = "default:steelblock", ["x"] = 4, ["y"] = 27}, {["z"] = 10, ["meta"] = {["inventory"] = {}, ["fields"] = {}}, ["param1"] = 82, ["name"] = "default:steelblock", ["x"] = 4, ["y"] = 27}, {["z"] = 11, ["meta"] = {["inventory"] = {}, ["fields"] = {}}, ["param1"] = 82, ["name"] = "default:steelblock", ["x"] = 4, ["y"] = 27}, {["z"] = 12, ["meta"] = {["inventory"] = {}, ["fields"] = {}}, ["param1"] = 82, ["name"] = "default:steelblock", ["x"] = 4, ["y"] = 27}, {["z"] = 13, ["meta"] = {["inventory"] = {}, ["fields"] = {}}, ["param1"] = 82, ["name"] = "default:steelblock", ["x"] = 4, ["y"] = 27}, {["z"] = 14, ["name"] = "wool:grey", ["x"] = 4, ["y"] = 27}, {["z"] = 7, ["meta"] = {["inventory"] = {}, ["fields"] = {}}, ["param1"] = 82, ["name"] = "default:steelblock", ["x"] = 4, ["y"] = 28}, {["z"] = 8, ["meta"] = {["inventory"] = {}, ["fields"] = {}}, ["param1"] = 82, ["name"] = "default:steelblock", ["x"] = 4, ["y"] = 28}, {["z"] = 9, ["meta"] = {["inventory"] = {}, ["fields"] = {}}, ["param1"] = 82, ["name"] = "default:steelblock", ["x"] = 4, ["y"] = 28}, {["z"] = 10, ["meta"] = {["inventory"] = {}, ["fields"] = {}}, ["param1"] = 82, ["name"] = "default:steelblock", ["x"] = 4, ["y"] = 28}, {["z"] = 11, ["meta"] = {["inventory"] = {}, ["fields"] = {}}, ["param1"] = 82, ["name"] = "default:steelblock", ["x"] = 4, ["y"] = 28}, {["z"] = 12, ["meta"] = {["inventory"] = {}, ["fields"] = {}}, ["param1"] = 82, ["name"] = "default:steelblock", ["x"] = 4, ["y"] = 28}, {["z"] = 13, ["meta"] = {["inventory"] = {}, ["fields"] = {}}, ["param1"] = 82, ["name"] = "default:steelblock", ["x"] = 4, ["y"] = 28}, {["z"] = 14, ["name"] = "wool:grey", ["x"] = 4, ["y"] = 28}, {["z"] = 15, ["meta"] = {["inventory"] = {}, ["fields"] = {}}, ["param1"] = 98, ["name"] = "wool:red", ["x"] = 4, ["y"] = 52}, {["z"] = 15, ["meta"] = {["inventory"] = {}, ["fields"] = {}}, ["param1"] = 98, ["name"] = "wool:red", ["x"] = 4, ["y"] = 53}, {["z"] = 15, ["meta"] = {["inventory"] = {}, ["fields"] = {}}, ["param1"] = 98, ["name"] = "wool:red", ["x"] = 4, ["y"] = 54}, {["z"] = 15, ["meta"] = {["inventory"] = {}, ["fields"] = {}}, ["param1"] = 98, ["name"] = "wool:red", ["x"] = 4, ["y"] = 55}, {["z"] = 15, ["meta"] = {["inventory"] = {}, ["fields"] = {}}, ["param1"] = 98, ["name"] = "wool:red", ["x"] = 4, ["y"] = 56}, {["z"] = 15, ["meta"] = {["inventory"] = {}, ["fields"] = {}}, ["param1"] = 98, ["name"] = "wool:red", ["x"] = 4, ["y"] = 57}, {["z"] = 15, ["meta"] = {["inventory"] = {}, ["fields"] = {}}, ["param1"] = 98, ["name"] = "wool:red", ["x"] = 4, ["y"] = 58}, {["z"] = 15, ["meta"] = {["inventory"] = {}, ["fields"] = {}}, ["param1"] = 98, ["name"] = "wool:red", ["x"] = 4, ["y"] = 59}, {["z"] = 7, ["meta"] = {["inventory"] = {}, ["fields"] = {}}, ["name"] = "default:steelblock", ["x"] = 5, ["y"] = 3}, {["z"] = 8, ["meta"] = {["inventory"] = {}, ["fields"] = {}}, ["name"] = "default:steelblock", ["x"] = 5, ["y"] = 3}, {["z"] = 9, ["meta"] = {["inventory"] = {}, ["fields"] = {}}, ["name"] = "default:steelblock", ["x"] = 5, ["y"] = 3}, {["z"] = 10, ["meta"] = {["inventory"] = {}, ["fields"] = {}}, ["name"] = "default:steelblock", ["x"] = 5, ["y"] = 3}, {["z"] = 11, ["meta"] = {["inventory"] = {}, ["fields"] = {}}, ["name"] = "default:steelblock", ["x"] = 5, ["y"] = 3}, {["z"] = 12, ["meta"] = {["inventory"] = {}, ["fields"] = {}}, ["name"] = "default:steelblock", ["x"] = 5, ["y"] = 3}, {["z"] = 13, ["meta"] = {["inventory"] = {}, ["fields"] = {}}, ["name"] = "default:steelblock", ["x"] = 5, ["y"] = 3}, {["z"] = 7, ["meta"] = {["inventory"] = {}, ["fields"] = {}}, ["name"] = "default:steelblock", ["x"] = 5, ["y"] = 4}, {["z"] = 8, ["meta"] = {["inventory"] = {}, ["fields"] = {}}, ["name"] = "default:steelblock", ["x"] = 5, ["y"] = 4}, {["z"] = 9, ["meta"] = {["inventory"] = {}, ["fields"] = {}}, ["name"] = "default:steelblock", ["x"] = 5, ["y"] = 4}, {["z"] = 10, ["meta"] = {["inventory"] = {}, ["fields"] = {}}, ["name"] = "default:steelblock", ["x"] = 5, ["y"] = 4}, {["z"] = 11, ["meta"] = {["inventory"] = {}, ["fields"] = {}}, ["name"] = "default:steelblock", ["x"] = 5, ["y"] = 4}, {["z"] = 12, ["meta"] = {["inventory"] = {}, ["fields"] = {}}, ["name"] = "default:steelblock", ["x"] = 5, ["y"] = 4}, {["z"] = 13, ["meta"] = {["inventory"] = {}, ["fields"] = {}}, ["name"] = "default:steelblock", ["x"] = 5, ["y"] = 4}, {["z"] = 2, ["meta"] = {["inventory"] = {}, ["fields"] = {}}, ["param1"] = 82, ["name"] = "default:steelblock", ["x"] = 5, ["y"] = 5}, {["z"] = 3, ["meta"] = {["inventory"] = {}, ["fields"] = {}}, ["param1"] = 82, ["name"] = "default:steelblock", ["x"] = 5, ["y"] = 5}, {["z"] = 4, ["meta"] = {["inventory"] = {}, ["fields"] = {}}, ["param1"] = 82, ["name"] = "default:steelblock", ["x"] = 5, ["y"] = 5}, {["z"] = 5, ["meta"] = {["inventory"] = {}, ["fields"] = {}}, ["param1"] = 82, ["name"] = "default:steelblock", ["x"] = 5, ["y"] = 5}, {["z"] = 6, ["meta"] = {["inventory"] = {}, ["fields"] = {}}, ["param1"] = 82, ["name"] = "default:steelblock", ["x"] = 5, ["y"] = 5}, {["z"] = 7, ["meta"] = {["inventory"] = {}, ["fields"] = {}}, ["param1"] = 82, ["name"] = "default:steelblock", ["x"] = 5, ["y"] = 5}, {["z"] = 8, ["meta"] = {["inventory"] = {}, ["fields"] = {}}, ["param1"] = 82, ["name"] = "default:steelblock", ["x"] = 5, ["y"] = 5}, {["z"] = 9, ["meta"] = {["inventory"] = {}, ["fields"] = {}}, ["param1"] = 82, ["name"] = "default:steelblock", ["x"] = 5, ["y"] = 5}, {["z"] = 10, ["meta"] = {["inventory"] = {}, ["fields"] = {}}, ["param1"] = 82, ["name"] = "default:steelblock", ["x"] = 5, ["y"] = 5}, {["z"] = 11, ["meta"] = {["inventory"] = {}, ["fields"] = {}}, ["param1"] = 82, ["name"] = "default:steelblock", ["x"] = 5, ["y"] = 5}, {["z"] = 12, ["meta"] = {["inventory"] = {}, ["fields"] = {}}, ["param1"] = 82, ["name"] = "default:steelblock", ["x"] = 5, ["y"] = 5}, {["z"] = 13, ["meta"] = {["inventory"] = {}, ["fields"] = {}}, ["param1"] = 82, ["name"] = "default:steelblock", ["x"] = 5, ["y"] = 5}, {["z"] = 14, ["meta"] = {["inventory"] = {}, ["fields"] = {}}, ["name"] = "wool:grey", ["x"] = 5, ["y"] = 5}, {["z"] = 1, ["meta"] = {["inventory"] = {}, ["fields"] = {}}, ["param1"] = 87, ["name"] = "wool:grey", ["x"] = 5, ["y"] = 6}, {["z"] = 2, ["meta"] = {["inventory"] = {}, ["fields"] = {}}, ["param1"] = 82, ["name"] = "default:steelblock", ["x"] = 5, ["y"] = 6}, {["z"] = 3, ["meta"] = {["inventory"] = {}, ["fields"] = {}}, ["param1"] = 82, ["name"] = "default:steelblock", ["x"] = 5, ["y"] = 6}, {["z"] = 4, ["meta"] = {["inventory"] = {}, ["fields"] = {}}, ["param1"] = 82, ["name"] = "default:steelblock", ["x"] = 5, ["y"] = 6}, {["z"] = 5, ["meta"] = {["inventory"] = {}, ["fields"] = {}}, ["param1"] = 82, ["name"] = "default:steelblock", ["x"] = 5, ["y"] = 6}, {["z"] = 6, ["meta"] = {["inventory"] = {}, ["fields"] = {}}, ["param1"] = 82, ["name"] = "default:steelblock", ["x"] = 5, ["y"] = 6}, {["z"] = 7, ["meta"] = {["inventory"] = {}, ["fields"] = {}}, ["param1"] = 82, ["name"] = "default:steelblock", ["x"] = 5, ["y"] = 6}, {["z"] = 8, ["meta"] = {["inventory"] = {}, ["fields"] = {}}, ["param1"] = 82, ["name"] = "default:steelblock", ["x"] = 5, ["y"] = 6}, {["z"] = 9, ["meta"] = {["inventory"] = {}, ["fields"] = {}}, ["param1"] = 82, ["name"] = "default:steelblock", ["x"] = 5, ["y"] = 6}, {["z"] = 10, ["meta"] = {["inventory"] = {}, ["fields"] = {}}, ["param1"] = 82, ["name"] = "default:steelblock", ["x"] = 5, ["y"] = 6}, {["z"] = 11, ["meta"] = {["inventory"] = {}, ["fields"] = {}}, ["param1"] = 82, ["name"] = "default:steelblock", ["x"] = 5, ["y"] = 6}, {["z"] = 12, ["meta"] = {["inventory"] = {}, ["fields"] = {}}, ["param1"] = 82, ["name"] = "default:steelblock", ["x"] = 5, ["y"] = 6}, {["z"] = 13, ["meta"] = {["inventory"] = {}, ["fields"] = {}}, ["param1"] = 82, ["name"] = "default:steelblock", ["x"] = 5, ["y"] = 6}, {["z"] = 14, ["meta"] = {["inventory"] = {}, ["fields"] = {}}, ["name"] = "wool:grey", ["x"] = 5, ["y"] = 6}, {["z"] = 2, ["meta"] = {["inventory"] = {}, ["fields"] = {}}, ["param1"] = 82, ["name"] = "default:steelblock", ["x"] = 5, ["y"] = 7}, {["z"] = 3, ["meta"] = {["inventory"] = {}, ["fields"] = {}}, ["param1"] = 82, ["name"] = "default:steelblock", ["x"] = 5, ["y"] = 7}, {["z"] = 4, ["meta"] = {["inventory"] = {}, ["fields"] = {}}, ["param1"] = 82, ["name"] = "default:steelblock", ["x"] = 5, ["y"] = 7}, {["z"] = 5, ["meta"] = {["inventory"] = {}, ["fields"] = {}}, ["param1"] = 82, ["name"] = "default:steelblock", ["x"] = 5, ["y"] = 7}, {["z"] = 6, ["meta"] = {["inventory"] = {}, ["fields"] = {}}, ["param1"] = 82, ["name"] = "default:steelblock", ["x"] = 5, ["y"] = 7}, {["z"] = 7, ["meta"] = {["inventory"] = {}, ["fields"] = {}}, ["param1"] = 82, ["name"] = "default:steelblock", ["x"] = 5, ["y"] = 7}, {["z"] = 8, ["meta"] = {["inventory"] = {}, ["fields"] = {}}, ["param1"] = 82, ["name"] = "default:steelblock", ["x"] = 5, ["y"] = 7}, {["z"] = 9, ["meta"] = {["inventory"] = {}, ["fields"] = {}}, ["param1"] = 82, ["name"] = "default:steelblock", ["x"] = 5, ["y"] = 7}, {["z"] = 10, ["meta"] = {["inventory"] = {}, ["fields"] = {}}, ["param1"] = 82, ["name"] = "default:steelblock", ["x"] = 5, ["y"] = 7}, {["z"] = 11, ["meta"] = {["inventory"] = {}, ["fields"] = {}}, ["param1"] = 82, ["name"] = "default:steelblock", ["x"] = 5, ["y"] = 7}, {["z"] = 12, ["meta"] = {["inventory"] = {}, ["fields"] = {}}, ["param1"] = 82, ["name"] = "default:steelblock", ["x"] = 5, ["y"] = 7}, {["z"] = 13, ["meta"] = {["inventory"] = {}, ["fields"] = {}}, ["param1"] = 82, ["name"] = "default:steelblock", ["x"] = 5, ["y"] = 7}, {["z"] = 14, ["meta"] = {["inventory"] = {}, ["fields"] = {}}, ["name"] = "wool:grey", ["x"] = 5, ["y"] = 7}, {["z"] = 2, ["meta"] = {["inventory"] = {}, ["fields"] = {}}, ["param1"] = 82, ["name"] = "default:steelblock", ["x"] = 5, ["y"] = 8}, {["z"] = 3, ["meta"] = {["inventory"] = {}, ["fields"] = {}}, ["param1"] = 82, ["name"] = "default:steelblock", ["x"] = 5, ["y"] = 8}, {["z"] = 4, ["meta"] = {["inventory"] = {}, ["fields"] = {}}, ["param1"] = 82, ["name"] = "default:steelblock", ["x"] = 5, ["y"] = 8}, {["z"] = 5, ["meta"] = {["inventory"] = {}, ["fields"] = {}}, ["param1"] = 82, ["name"] = "default:steelblock", ["x"] = 5, ["y"] = 8}, {["z"] = 6, ["meta"] = {["inventory"] = {}, ["fields"] = {}}, ["param1"] = 82, ["name"] = "default:steelblock", ["x"] = 5, ["y"] = 8}, {["z"] = 7, ["meta"] = {["inventory"] = {}, ["fields"] = {}}, ["param1"] = 82, ["name"] = "default:steelblock", ["x"] = 5, ["y"] = 8}, {["z"] = 8, ["meta"] = {["inventory"] = {}, ["fields"] = {}}, ["param1"] = 82, ["name"] = "default:steelblock", ["x"] = 5, ["y"] = 8}, {["z"] = 9, ["meta"] = {["inventory"] = {}, ["fields"] = {}}, ["param1"] = 82, ["name"] = "default:steelblock", ["x"] = 5, ["y"] = 8}, {["z"] = 10, ["meta"] = {["inventory"] = {}, ["fields"] = {}}, ["param1"] = 82, ["name"] = "default:steelblock", ["x"] = 5, ["y"] = 8}, {["z"] = 11, ["meta"] = {["inventory"] = {}, ["fields"] = {}}, ["param1"] = 82, ["name"] = "default:steelblock", ["x"] = 5, ["y"] = 8}, {["z"] = 12, ["meta"] = {["inventory"] = {}, ["fields"] = {}}, ["param1"] = 82, ["name"] = "default:steelblock", ["x"] = 5, ["y"] = 8}, {["z"] = 13, ["meta"] = {["inventory"] = {}, ["fields"] = {}}, ["param1"] = 82, ["name"] = "default:steelblock", ["x"] = 5, ["y"] = 8}, {["z"] = 14, ["meta"] = {["inventory"] = {}, ["fields"] = {}}, ["name"] = "wool:grey", ["x"] = 5, ["y"] = 8}, {["z"] = 1, ["meta"] = {["inventory"] = {}, ["fields"] = {}}, ["param1"] = 87, ["name"] = "wool:grey", ["x"] = 5, ["y"] = 9}, {["z"] = 2, ["meta"] = {["inventory"] = {}, ["fields"] = {}}, ["param1"] = 82, ["name"] = "default:steelblock", ["x"] = 5, ["y"] = 9}, {["z"] = 3, ["meta"] = {["inventory"] = {}, ["fields"] = {}}, ["param1"] = 82, ["name"] = "default:steelblock", ["x"] = 5, ["y"] = 9}, {["z"] = 4, ["meta"] = {["inventory"] = {}, ["fields"] = {}}, ["param1"] = 82, ["name"] = "default:steelblock", ["x"] = 5, ["y"] = 9}, {["z"] = 5, ["meta"] = {["inventory"] = {}, ["fields"] = {}}, ["param1"] = 82, ["name"] = "default:steelblock", ["x"] = 5, ["y"] = 9}, {["z"] = 6, ["meta"] = {["inventory"] = {}, ["fields"] = {}}, ["param1"] = 82, ["name"] = "default:steelblock", ["x"] = 5, ["y"] = 9}, {["z"] = 7, ["meta"] = {["inventory"] = {}, ["fields"] = {}}, ["param1"] = 82, ["name"] = "default:steelblock", ["x"] = 5, ["y"] = 9}, {["z"] = 8, ["meta"] = {["inventory"] = {}, ["fields"] = {}}, ["param1"] = 82, ["name"] = "default:steelblock", ["x"] = 5, ["y"] = 9}, {["z"] = 9, ["meta"] = {["inventory"] = {}, ["fields"] = {}}, ["param1"] = 82, ["name"] = "default:steelblock", ["x"] = 5, ["y"] = 9}, {["z"] = 10, ["meta"] = {["inventory"] = {}, ["fields"] = {}}, ["param1"] = 82, ["name"] = "default:steelblock", ["x"] = 5, ["y"] = 9}, {["z"] = 11, ["meta"] = {["inventory"] = {}, ["fields"] = {}}, ["param1"] = 82, ["name"] = "default:steelblock", ["x"] = 5, ["y"] = 9}, {["z"] = 12, ["meta"] = {["inventory"] = {}, ["fields"] = {}}, ["param1"] = 82, ["name"] = "default:steelblock", ["x"] = 5, ["y"] = 9}, {["z"] = 13, ["meta"] = {["inventory"] = {}, ["fields"] = {}}, ["param1"] = 82, ["name"] = "default:steelblock", ["x"] = 5, ["y"] = 9}, {["z"] = 14, ["meta"] = {["inventory"] = {}, ["fields"] = {}}, ["name"] = "wool:grey", ["x"] = 5, ["y"] = 9}, {["z"] = 2, ["meta"] = {["inventory"] = {}, ["fields"] = {}},